Workbook

Sheet 📋 Portada
B3: HUELLA SOCIAL — COOPERATIVAS DE AHORRO Y CRÉDITO
B6: Cuenta Satélite del Sector Cooperativo Financiero Chileno
B10: CONTENIDO DEL ARCHIVO
B12: 📊 1. Agregados DAES
B13: Totales anuales 2014–2024 del segmento no supervisado por CMF. Incluye P1, B1g, D1, B2g, Rem, PIB y Aporte (%).
B15: 🏦 2. Agregados CMF
B16: Totales anuales 2014–2025 de las 7 CAC supervisadas por CMF. Incluye P1, B1g, Rem, activos, depósitos y colocaciones.
B18: 📅 3. CMF Feb-2026
B19: Resultados acumulados enero–febrero 2026 de las 7 CAC CMF. Datos parciales (2 meses); incluye B1g anualizado y aporte referencial.
B21: 📁 4. Panel DAES
B22: Una fila por cooperativa×año. Todas las entidades DAES con sus variables de cuenta de producción y balance.
B24: 📁 5. Panel CMF
... B39: • Coopeuch aparece en DAES hasta 2016 (supervisada por SBIF). Desde 2017 figura en el panel CMF.

Sheet 📊 Agregados DAES
A1: CUENTA DE PRODUCCIÓN Y GENERACIÓN DEL INGRESO — SEGMENTO DAES (CAC no supervisadas por CMF)
A2: Cifras en millones de pesos corrientes (MM$). P1 = Total Ingresos Operación | P2 = α×P1 (α=0,3776) | B1g = P1−P2 | PIB: Banco Central, ref. 2018
A3: Año | B3: N | C3: P1 (MM$) | D3: P2 (MM$) | E3: B1g (MM$) | F3: D1 (MM$) | G3: B2g (MM$) | H3: Rem (MM$) | I3: D1/B1g | J3: PIB Chile (MM$) | K3: Aporte (%)
A4: 2014 | B4: =+COUNTIFS('📁 Panel DAES'!$D$3:$D$135,'📊 Agregados DAES'!A4,'📁 Panel DAES'!$E$3:$E$135,"<>",'📁 Panel DAES'!$H$3:$H$135,"<>") -> 2 | C4: =+SUMIF('📁 Panel DAES'!$D$3:$D$135,'📊 Agregados DAES'!A4,'📁 Panel DAES'!$E$3:$E$135) -> 247.89282 | D4: =0.3776*C4 -> 93.604329 | E4: =+C4-D4 -> 154.28849 | F4: =+SUMIF('📁 Panel DAES'!$D$3:$D$135,'📊 Agregados DAES'!A4,'📁 Panel DAES'!$H$3:$H$135) -> 78.223597 | G4: =+E4-F4 -> 76.064894 | H4: =+SUMIF('📁 Panel DAES'!$D$3:$D$135,'📊 Agregados DAES'!A4,'📁 Panel DAES'!$J$3:$J$135) -> -6.852924 | I4: =+F4/E4 -> 0.50699567 | J4: 144706000 | K4: =+(E4/J4)*100 -> 0.00010662204
A5: 2015 | B5: =+COUNTIFS('📁 Panel DAES'!$D$3:$D$135,'📊 Agregados DAES'!A5,'📁 Panel DAES'!$E$3:$E$135,"<>",'📁 Panel DAES'!$H$3:$H$135,"<>") -> 7 | C5: =+SUMIF('📁 Panel DAES'!$D$3:$D$135,'📊 Agregados DAES'!A5,'📁 Panel DAES'!$E$3:$E$135) -> 5426.0644 | D5: =0.3776*C5 -> 2048.8819 | E5: =+C5-D5 -> 3377.1825 | F5: =+SUMIF('📁 Panel DAES'!$D$3:$D$135,'📊 Agregados DAES'!A5,'📁 Panel DAES'!$H$3:$H$135) -> 1762.8158 | G5: =+E5-F5 -> 1614.3667 | H5: =+SUMIF('📁 Panel DAES'!$D$3:$D$135,'📊 Agregados DAES'!A5,'📁 Panel DAES'!$J$3:$J$135) -> 740.60321 | I5: =+F5/E5 -> 0.52197825 | J5: 158623000 | K5: =+(E5/J5)*100 -> 0.0021290623
A6: 2016 | B6: =+COUNTIFS('📁 Panel DAES'!$D$3:$D$135,'📊 Agregados DAES'!A6,'📁 Panel DAES'!$E$3:$E$135,"<>",'📁 Panel DAES'!$H$3:$H$135,"<>") -> 9 | C6: =+SUMIF('📁 Panel DAES'!$D$3:$D$135,'📊 Agregados DAES'!A6,'📁 Panel DAES'!$E$3:$E$135) -> 6083.2353 | D6: =0.3776*C6 -> 2297.0296 | E6: =+C6-D6 -> 3786.2056 | F6: =+SUMIF('📁 Panel DAES'!$D$3:$D$135,'📊 Agregados DAES'!A6,'📁 Panel DAES'!$H$3:$H$135) -> 2000.2757 | G6: =+E6-F6 -> 1785.9299 | H6: =+SUMIF('📁 Panel DAES'!$D$3:$D$135,'📊 Agregados DAES'!A6,'📁 Panel DAES'!$J$3:$J$135) -> 350.45645 | I6: =+F6/E6 -> 0.52830614 | J6: 168765000 | K6: =+(E6/J6)*100 -> 0.002243478
A7: 2017 | B7: =+COUNTIFS('📁 Panel DAES'!$D$3:$D$135,'📊 Agregados DAES'!A7,'📁 Panel DAES'!$E$3:$E$135,"<>",'📁 Panel DAES'!$H$3:$H$135,"<>") -> 12 | C7: =+SUMIF('📁 Panel DAES'!$D$3:$D$135,'📊 Agregados DAES'!A7,'📁 Panel DAES'!$E$3:$E$135) -> 6224.2481 | D7: =0.3776*C7 -> 2350.2761 | E7: =+C7-D7 -> 3873.972 | F7: =+SUMIF('📁 Panel DAES'!$D$3:$D$135,'📊 Agregados DAES'!A7,'📁 Panel DAES'!$H$3:$H$135) -> 2622.2251 | G7: =+E7-F7 -> 1251.7469 | H7: =+SUMIF('📁 Panel DAES'!$D$3:$D$135,'📊 Agregados DAES'!A7,'📁 Panel DAES'!$J$3:$J$135) -> 260.27679 | I7: =+F7/E7 -> 0.67688283 | J7: 179315000 | K7: =+(E7/J7)*100 -> 0.0021604283
A8: 2018 | B8: =+COUNTIFS('📁 Panel DAES'!$D$3:$D$135,'📊 Agregados DAES'!A8,'📁 Panel DAES'!$E$3:$E$135,"<>",'📁 Panel DAES'!$H$3:$H$135,"<>") -> 14 | C8: =+SUMIF('📁 Panel DAES'!$D$3:$D$135,'📊 Agregados DAES'!A8,'📁 Panel DAES'!$E$3:$E$135) -> 8977.2604 | D8: =0.3776*C8 -> 3389.8135 | E8: =+C8-D8 -> 5587.4469 | F8: =+SUMIF('📁 Panel DAES'!$D$3:$D$135,'📊 Agregados DAES'!A8,'📁 Panel DAES'!$H$3:$H$135) -> 4385.2416 | G8: =+E8-F8 -> 1202.2052 | H8: =+SUMIF('📁 Panel DAES'!$D$3:$D$135,'📊 Agregados DAES'!A8,'📁 Panel DAES'!$J$3:$J$135) -> 628.3566 | I8: =+F8/E8 -> 0.78483818 | J8: 189435000 | K8: =+(E8/J8)*100 -> 0.0029495325
A9: 2019 | B9: =+COUNTIFS('📁 Panel DAES'!$D$3:$D$135,'📊 Agregados DAES'!A9,'📁 Panel DAES'!$E$3:$E$135,"<>",'📁 Panel DAES'!$H$3:$H$135,"<>") -> 6 | C9: =+SUMIF('📁 Panel DAES'!$D$3:$D$135,'📊 Agregados DAES'!A9,'📁 Panel DAES'!$E$3:$E$135) -> 4667.2517 | D9: =0.3776*C9 -> 1762.3542 | E9: =+C9-D9 -> 2904.8974 | F9: =+SUMIF('📁 Panel DAES'!$D$3:$D$135,'📊 Agregados DAES'!A9,'📁 Panel DAES'!$H$3:$H$135) -> 1854.9876 | G9: =+E9-F9 -> 1049.9099 | H9: =+SUMIF('📁 Panel DAES'!$D$3:$D$135,'📊 Agregados DAES'!A9,'📁 Panel DAES'!$J$3:$J$135) -> 503.36676 | I9: =+F9/E9 -> 0.63857248 | J9: 195548000 | K9: =+(E9/J9)*100 -> 0.0014855163
A10: 2020 | B10: =+COUNTIFS('📁 Panel DAES'!$D$3:$D$135,'📊 Agregados DAES'!A10,'📁 Panel DAES'!$E$3:$E$135,"<>",'📁 Panel DAES'!$H$3:$H$135,"<>") -> 10 | C10: =+SUMIF('📁 Panel DAES'!$D$3:$D$135,'📊 Agregados DAES'!A10,'📁 Panel DAES'!$E$3:$E$135) -> 6164.6371 | D10: =0.3776*C10 -> 2327.767 | E10: =+C10-D10 -> 3836.8702 | F10: =+SUMIF('📁 Panel DAES'!$D$3:$D$135,'📊 Agregados DAES'!A10,'📁 Panel DAES'!$H$3:$H$135) -> 2419.9054 | G10: =+E10-F10 -> 1416.9648 | H10: =+SUMIF('📁 Panel DAES'!$D$3:$D$135,'📊 Agregados DAES'!A10,'📁 Panel DAES'!$J$3:$J$135) -> 155.04948 | I10: =+F10/E10 -> 0.63069776 | J10: 201307000 | K10: =+(E10/J10)*100 -> 0.0019059795
A11: 2021 | B11: =+COUNTIFS('📁 Panel DAES'!$D$3:$D$135,'📊 Agregados DAES'!A11,'📁 Panel DAES'!$E$3:$E$135,"<>",'📁 Panel DAES'!$H$3:$H$135,"<>") -> 10 | C11: =+SUMIF('📁 Panel DAES'!$D$3:$D$135,'📊 Agregados DAES'!A11,'📁 Panel DAES'!$E$3:$E$135) -> 6010.5201 | D11: =0.3776*C11 -> 2269.5724 | E11: =+C11-D11 -> 3740.9477 | F11: =+SUMIF('📁 Panel DAES'!$D$3:$D$135,'📊 Agregados DAES'!A11,'📁 Panel DAES'!$H$3:$H$135) -> 2030.0232 | G11: =+E11-F11 -> 1710.9245 | H11: =+SUMIF('📁 Panel DAES'!$D$3:$D$135,'📊 Agregados DAES'!A11,'📁 Panel DAES'!$J$3:$J$135) -> 29.251521 | I11: =+F11/E11 -> 0.54264944 | J11: 239556000 | K11: =+(E11/J11)*100 -> 0.0015616172
A12: 2022 | B12: =+COUNTIFS('📁 Panel DAES'!$D$3:$D$135,'📊 Agregados DAES'!A12,'📁 Panel DAES'!$E$3:$E$135,"<>",'📁 Panel DAES'!$H$3:$H$135,"<>") -> 19 | C12: =+SUMIF('📁 Panel DAES'!$D$3:$D$135,'📊 Agregados DAES'!A12,'📁 Panel DAES'!$E$3:$E$135) -> 22171.988 | D12: =0.3776*C12 -> 8372.1428 | E12: =+C12-D12 -> 13799.846 | F12: =+SUMIF('📁 Panel DAES'!$D$3:$D$135,'📊 Agregados DAES'!A12,'📁 Panel DAES'!$H$3:$H$135) -> 6967.3719 | G12: =+E12-F12 -> 6832.4737 | H12: =+SUMIF('📁 Panel DAES'!$D$3:$D$135,'📊 Agregados DAES'!A12,'📁 Panel DAES'!$J$3:$J$135) -> -2572.8427 | I12: =+F12/E12 -> 0.50488767 | J12: 262954000 | K12: =+(E12/J12)*100 -> 0.0052480075
A13: 2023 | B13: =+COUNTIFS('📁 Panel DAES'!$D$3:$D$135,'📊 Agregados DAES'!A13,'📁 Panel DAES'!$E$3:$E$135,"<>",'📁 Panel DAES'!$H$3:$H$135,"<>") -> 22 | C13: =+SUMIF('📁 Panel DAES'!$D$3:$D$135,'📊 Agregados DAES'!A13,'📁 Panel DAES'!$E$3:$E$135) -> 47404.627 | D13: =0.3776*C13 -> 17899.987 | E13: =+C13-D13 -> 29504.64 | F13: =+SUMIF('📁 Panel DAES'!$D$3:$D$135,'📊 Agregados DAES'!A13,'📁 Panel DAES'!$H$3:$H$135) -> 12582.384 | G13: =+E13-F13 -> 16922.255 | H13: =+SUMIF('📁 Panel DAES'!$D$3:$D$135,'📊 Agregados DAES'!A13,'📁 Panel DAES'!$J$3:$J$135) -> 2542.8579 | I13: =+F13/E13 -> 0.42645443 | J13: 282097000 | K13: =+(E13/J13)*100 -> 0.010459041
A14: 2024 | B14: =+COUNTIFS('📁 Panel DAES'!$D$3:$D$135,'📊 Agregados DAES'!A14,'📁 Panel DAES'!$E$3:$E$135,"<>",'📁 Panel DAES'!$H$3:$H$135,"<>") -> 11 | C14: =+SUMIF('📁 Panel DAES'!$D$3:$D$135,'📊 Agregados DAES'!A14,'📁 Panel DAES'!$E$3:$E$135) -> 18135.86 | D14: =0.3776*C14 -> 6848.1009 | E14: =+C14-D14 -> 11287.759 | F14: =+SUMIF('📁 Panel DAES'!$D$3:$D$135,'📊 Agregados DAES'!A14,'📁 Panel DAES'!$H$3:$H$135) -> 8269.4476 | G14: =+E14-F14 -> 3018.3119 | H14: =+SUMIF('📁 Panel DAES'!$D$3:$D$135,'📊 Agregados DAES'!A14,'📁 Panel DAES'!$J$3:$J$135) -> 2246.7217 | I14: =+F14/E14 -> 0.7326031 | J14: 310681000 | K14: =+(E14/J14)*100 -> 0.0036332313
A15: TOTAL PERÍODO | C15: =+SUM(C4:C14) -> 131513.59 | D15: =+SUM(D4:D14) -> 49659.53 | E15: =+SUM(E4:E14) -> 81854.055 | F15: =+SUM(F4:F14) -> 44972.902 | G15: =+SUM(G4:G14) -> 36881.154 | H15: =+SUM(H4:H14) -> 4877.2447 | I15: — | J15: — | K15: —
A17: CUENTA FINANCIERA — BALANCE GENERAL
A18: F2 = Depósitos captados (vista + plazo) | F4 = Colocaciones netas (total − provisiones)
A19: Año | B19: N | C19: Activos (MM$) | D19: Patrimonio (MM$) | E19: F2 Depósitos (MM$) | F19: F4 Colocaciones (MM$) | G19: F4/Activos | H19: F2/Activos
A20: 2014 | B20: =+COUNTIFS('📁 Panel DAES'!$D$3:$D$135,'📊 Agregados DAES'!A20,'📁 Panel DAES'!$K$3:$K$135,"<>",'📁 Panel DAES'!$L$3:$L$135,"<>",'📁 Panel DAES'!$M$3:$M$135,"<>",'📁 Panel DAES'!$N$3:$N$135,"<>") -> 2 | C20: =+SUMIF('📁 Panel DAES'!$D$3:$D$135,'📊 Agregados DAES'!A20,'📁 Panel DAES'!$K$3:$K$135) -> 1226.5979 | D20: =+SUMIF('📁 Panel DAES'!$D$3:$D$135,'📊 Agregados DAES'!A20,'📁 Panel DAES'!$L$3:$L$135) -> 1132.5209 | E20: =+SUMIF('📁 Panel DAES'!$D$3:$D$135,'📊 Agregados DAES'!A20,'📁 Panel DAES'!$M$3:$M$135) -> 72.623722 | F20: =+SUMIF('📁 Panel DAES'!$D$3:$D$135,'📊 Agregados DAES'!A20,'📁 Panel DAES'!$N$3:$N$135) -> 847.35116 | G20: =+F20/C20 -> 0.69081411 | H20: =+E20/C20 -> 0.059207439
A21: 2015 | B21: =+COUNTIFS('📁 Panel DAES'!$D$3:$D$135,'📊 Agregados DAES'!A21,'📁 Panel DAES'!$K$3:$K$135,"<>",'📁 Panel DAES'!$L$3:$L$135,"<>",'📁 Panel DAES'!$M$3:$M$135,"<>",'📁 Panel DAES'!$N$3:$N$135,"<>") -> 7 | C21: =+SUMIF('📁 Panel DAES'!$D$3:$D$135,'📊 Agregados DAES'!A21,'📁 Panel DAES'!$K$3:$K$135) -> 32039.86 | D21: =+SUMIF('📁 Panel DAES'!$D$3:$D$135,'📊 Agregados DAES'!A21,'📁 Panel DAES'!$L$3:$L$135) -> 26762.114 | E21: =+SUMIF('📁 Panel DAES'!$D$3:$D$135,'📊 Agregados DAES'!A21,'📁 Panel DAES'!$M$3:$M$135) -> 4996.6645 | F21: =+SUMIF('📁 Panel DAES'!$D$3:$D$135,'📊 Agregados DAES'!A21,'📁 Panel DAES'!$N$3:$N$135) -> 23988.19 | G21: =+F21/C21 -> 0.74869834 | H21: =+E21/C21 -> 0.15595151
A22: 2016 | B22: =+COUNTIFS('📁 Panel DAES'!$D$3:$D$135,'📊 Agregados DAES'!A22,'📁 Panel DAES'!$K$3:$K$135,"<>",'📁 Panel DAES'!$L$3:$L$135,"<>",'📁 Panel DAES'!$M$3:$M$135,"<>",'📁 Panel DAES'!$N$3:$N$135,"<>") -> 7 | C22: =+SUMIF('📁 Panel DAES'!$D$3:$D$135,'📊 Agregados DAES'!A22,'📁 Panel DAES'!$K$3:$K$135) -> 10349.981 | D22: =+SUMIF('📁 Panel DAES'!$D$3:$D$135,'📊 Agregados DAES'!A22,'📁 Panel DAES'!$L$3:$L$135) -> 4680.602 | E22: =+SUMIF('📁 Panel DAES'!$D$3:$D$135,'📊 Agregados DAES'!A22,'📁 Panel DAES'!$M$3:$M$135) -> 5060.6694 | F22: =+SUMIF('📁 Panel DAES'!$D$3:$D$135,'📊 Agregados DAES'!A22,'📁 Panel DAES'!$N$3:$N$135) -> 7276.6831 | G22: =+F22/C22 -> 0.70306245 | H22: =+E22/C22 -> 0.48895446
A23: 2017 | B23: =+COUNTIFS('📁 Panel DAES'!$D$3:$D$135,'📊 Agregados DAES'!A23,'📁 Panel DAES'!$K$3:$K$135,"<>",'📁 Panel DAES'!$L$3:$L$135,"<>",'📁 Panel DAES'!$M$3:$M$135,"<>",'📁 Panel DAES'!$N$3:$N$135,"<>") -> 7 | C23: =+SUMIF('📁 Panel DAES'!$D$3:$D$135,'📊 Agregados DAES'!A23,'📁 Panel DAES'!$K$3:$K$135) -> 32452.608 | D23: =+SUMIF('📁 Panel DAES'!$D$3:$D$135,'📊 Agregados DAES'!A23,'📁 Panel DAES'!$L$3:$L$135) -> 17330.129 | E23: =+SUMIF('📁 Panel DAES'!$D$3:$D$135,'📊 Agregados DAES'!A23,'📁 Panel DAES'!$M$3:$M$135) -> 8733.3372 | F23: =+SUMIF('📁 Panel DAES'!$D$3:$D$135,'📊 Agregados DAES'!A23,'📁 Panel DAES'!$N$3:$N$135) -> 15278.378 | G23: =+F23/C23 -> 0.47079045 | H23: =+E23/C23 -> 0.26911049
A24: 2018 | B24: =+COUNTIFS('📁 Panel DAES'!$D$3:$D$135,'📊 Agregados DAES'!A24,'📁 Panel DAES'!$K$3:$K$135,"<>",'📁 Panel DAES'!$L$3:$L$135,"<>",'📁 Panel DAES'!$M$3:$M$135,"<>",'📁 Panel DAES'!$N$3:$N$135,"<>") -> 10 | C24: =+SUMIF('📁 Panel DAES'!$D$3:$D$135,'📊 Agregados DAES'!A24,'📁 Panel DAES'!$K$3:$K$135) -> 51825.685 | D24: =+SUMIF('📁 Panel DAES'!$D$3:$D$135,'📊 Agregados DAES'!A24,'📁 Panel DAES'!$L$3:$L$135) -> 19382.343 | E24: =+SUMIF('📁 Panel DAES'!$D$3:$D$135,'📊 Agregados DAES'!A24,'📁 Panel DAES'!$M$3:$M$135) -> 12619.894 | F24: =+SUMIF('📁 Panel DAES'!$D$3:$D$135,'📊 Agregados DAES'!A24,'📁 Panel DAES'!$N$3:$N$135) -> 29732.94 | G24: =+F24/C24 -> 0.57371051 | H24: =+E24/C24 -> 0.24350655
A25: 2019 | B25: =+COUNTIFS('📁 Panel DAES'!$D$3:$D$135,'📊 Agregados DAES'!A25,'📁 Panel DAES'!$K$3:$K$135,"<>",'📁 Panel DAES'!$L$3:$L$135,"<>",'📁 Panel DAES'!$M$3:$M$135,"<>",'📁 Panel DAES'!$N$3:$N$135,"<>") -> 6 | C25: =+SUMIF('📁 Panel DAES'!$D$3:$D$135,'📊 Agregados DAES'!A25,'📁 Panel DAES'!$K$3:$K$135) -> 33039.67 | D25: =+SUMIF('📁 Panel DAES'!$D$3:$D$135,'📊 Agregados DAES'!A25,'📁 Panel DAES'!$L$3:$L$135) -> 14893.597 | E25: =+SUMIF('📁 Panel DAES'!$D$3:$D$135,'📊 Agregados DAES'!A25,'📁 Panel DAES'!$M$3:$M$135) -> 15387.076 | F25: =+SUMIF('📁 Panel DAES'!$D$3:$D$135,'📊 Agregados DAES'!A25,'📁 Panel DAES'!$N$3:$N$135) -> 23618.052 | G25: =+F25/C25 -> 0.71483921 | H25: =+E25/C25 -> 0.46571517
A26: 2020 | B26: =+COUNTIFS('📁 Panel DAES'!$D$3:$D$135,'📊 Agregados DAES'!A26,'📁 Panel DAES'!$K$3:$K$135,"<>",'📁 Panel DAES'!$L$3:$L$135,"<>",'📁 Panel DAES'!$M$3:$M$135,"<>",'📁 Panel DAES'!$N$3:$N$135,"<>") -> 9 | C26: =+SUMIF('📁 Panel DAES'!$D$3:$D$135,'📊 Agregados DAES'!A26,'📁 Panel DAES'!$K$3:$K$135) -> 47098.723 | D26: =+SUMIF('📁 Panel DAES'!$D$3:$D$135,'📊 Agregados DAES'!A26,'📁 Panel DAES'!$L$3:$L$135) -> 23639.688 | E26: =+SUMIF('📁 Panel DAES'!$D$3:$D$135,'📊 Agregados DAES'!A26,'📁 Panel DAES'!$M$3:$M$135) -> 21306.056 | F26: =+SUMIF('📁 Panel DAES'!$D$3:$D$135,'📊 Agregados DAES'!A26,'📁 Panel DAES'!$N$3:$N$135) -> 27462.093 | G26: =+F26/C26 -> 0.58307509 | H26: =+E26/C26 -> 0.45237014
A27: 2021 | B27: =+COUNTIFS('📁 Panel DAES'!$D$3:$D$135,'📊 Agregados DAES'!A27,'📁 Panel DAES'!$K$3:$K$135,"<>",'📁 Panel DAES'!$L$3:$L$135,"<>",'📁 Panel DAES'!$M$3:$M$135,"<>",'📁 Panel DAES'!$N$3:$N$135,"<>") -> 8 | C27: =+SUMIF('📁 Panel DAES'!$D$3:$D$135,'📊 Agregados DAES'!A27,'📁 Panel DAES'!$K$3:$K$135) -> 46796.015 | D27: =+SUMIF('📁 Panel DAES'!$D$3:$D$135,'📊 Agregados DAES'!A27,'📁 Panel DAES'!$L$3:$L$135) -> 25103.643 | E27: =+SUMIF('📁 Panel DAES'!$D$3:$D$135,'📊 Agregados DAES'!A27,'📁 Panel DAES'!$M$3:$M$135) -> 19693.459 | F27: =+SUMIF('📁 Panel DAES'!$D$3:$D$135,'📊 Agregados DAES'!A27,'📁 Panel DAES'!$N$3:$N$135) -> 27701.892 | G27: =+F27/C27 -> 0.59197116 | H27: =+E27/C27 -> 0.42083624
A28: 2022 | B28: =+COUNTIFS('📁 Panel DAES'!$D$3:$D$135,'📊 Agregados DAES'!A28,'📁 Panel DAES'!$K$3:$K$135,"<>",'📁 Panel DAES'!$L$3:$L$135,"<>",'📁 Panel DAES'!$M$3:$M$135,"<>",'📁 Panel DAES'!$N$3:$N$135,"<>") -> 15 | C28: =+SUMIF('📁 Panel DAES'!$D$3:$D$135,'📊 Agregados DAES'!A28,'📁 Panel DAES'!$K$3:$K$135) -> 84588.66 | D28: =+SUMIF('📁 Panel DAES'!$D$3:$D$135,'📊 Agregados DAES'!A28,'📁 Panel DAES'!$L$3:$L$135) -> 46311.421 | E28: =+SUMIF('📁 Panel DAES'!$D$3:$D$135,'📊 Agregados DAES'!A28,'📁 Panel DAES'!$M$3:$M$135) -> 34145.43 | F28: =+SUMIF('📁 Panel DAES'!$D$3:$D$135,'📊 Agregados DAES'!A28,'📁 Panel DAES'!$N$3:$N$135) -> 56563.259 | G28: =+F28/C28 -> 0.66868608 | H28: =+E28/C28 -> 0.40366439
A29: 2023 | B29: =+COUNTIFS('📁 Panel DAES'!$D$3:$D$135,'📊 Agregados DAES'!A29,'📁 Panel DAES'!$K$3:$K$135,"<>",'📁 Panel DAES'!$L$3:$L$135,"<>",'📁 Panel DAES'!$M$3:$M$135,"<>",'📁 Panel DAES'!$N$3:$N$135,"<>") -> 18 | C29: =+SUMIF('📁 Panel DAES'!$D$3:$D$135,'📊 Agregados DAES'!A29,'📁 Panel DAES'!$K$3:$K$135) -> 165905.33 | D29: =+SUMIF('📁 Panel DAES'!$D$3:$D$135,'📊 Agregados DAES'!A29,'📁 Panel DAES'!$L$3:$L$135) -> 71655.962 | E29: =+SUMIF('📁 Panel DAES'!$D$3:$D$135,'📊 Agregados DAES'!A29,'📁 Panel DAES'!$M$3:$M$135) -> 87353.148 | F29: =+SUMIF('📁 Panel DAES'!$D$3:$D$135,'📊 Agregados DAES'!A29,'📁 Panel DAES'!$N$3:$N$135) -> 114808.28 | G29: =+F29/C29 -> 0.69201078 | H29: =+E29/C29 -> 0.52652406
A30: 2024 | B30: =+COUNTIFS('📁 Panel DAES'!$D$3:$D$135,'📊 Agregados DAES'!A30,'📁 Panel DAES'!$K$3:$K$135,"<>",'📁 Panel DAES'!$L$3:$L$135,"<>",'📁 Panel DAES'!$M$3:$M$135,"<>",'📁 Panel DAES'!$N$3:$N$135,"<>") -> 11 | C30: =+SUMIF('📁 Panel DAES'!$D$3:$D$135,'📊 Agregados DAES'!A30,'📁 Panel DAES'!$K$3:$K$135) -> 107922.7 | D30: =+SUMIF('📁 Panel DAES'!$D$3:$D$135,'📊 Agregados DAES'!A30,'📁 Panel DAES'!$L$3:$L$135) -> 44311.961 | E30: =+SUMIF('📁 Panel DAES'!$D$3:$D$135,'📊 Agregados DAES'!A30,'📁 Panel DAES'!$M$3:$M$135) -> 59798.903 | F30: =+SUMIF('📁 Panel DAES'!$D$3:$D$135,'📊 Agregados DAES'!A30,'📁 Panel DAES'!$N$3:$N$135) -> 81305.028 | G30: =+F30/C30 -> 0.75336356 | H30: =+E30/C30 -> 0.55409015
A31: TOTAL PERÍODO | C31: =+SUM(C20:C30) -> 613245.83 | D31: =+SUM(D20:D30) -> 295203.98 | E31: =+SUM(E20:E30) -> 269167.26 | F31: =+SUM(F20:F30) -> 408582.14 | G31: — | H31: —

Sheet 🏦 Agregados CMF
A1: CUENTA DE PRODUCCIÓN Y GENERACIÓN DEL INGRESO — SEGMENTO CMF (7 CAC supervisadas 2013–2025)
A2: P2 = α×P1 (α=0,3776) | B1g = P1−P2 | PIB: Banco Central ref. 2018
A3: Año | B3: N | C3: P1 (MM$) | D3: P2 (MM$) | E3: B1g (MM$) | F3: D1 (MM$) | G3: B2g (MM$) | H3: Rem (MM$) | I3: D1/B1g | J3: PIB Chile (MM$) | K3: Aporte (%)
A4: 2013 | B4: =+COUNTIF('📁 Panel CMF'!$D$3:$D$93,'🏦 Agregados CMF'!A4) -> 7 | C4: =+SUMIF('📁 Panel CMF'!$D$3:$D$93,'🏦 Agregados CMF'!A4,'📁 Panel CMF'!$E$3:$E$93) -> 260475 | D4: =0.3776*C4 -> 98355.36 | E4: =+C4-D4 -> 162119.64 | F4: =+SUMIF('📁 Panel CMF'!$D$3:$D$93,'🏦 Agregados CMF'!A4,'📁 Panel CMF'!$H$3:$H$93) -> 61877.3 | G4: =+E4-F4 -> 100242.34 | H4: =+SUMIF('📁 Panel CMF'!$D$3:$D$93,'🏦 Agregados CMF'!A4,'📁 Panel CMF'!$J$3:$J$93) -> 22868.4 | I4: =+F4/E4 -> 0.38167677 | J4: 136003000 | K4: =+(E4/J4)*100 -> 0.11920299
A5: 2014 | B5: =+COUNTIF('📁 Panel CMF'!$D$3:$D$93,'🏦 Agregados CMF'!A5) -> 7 | C5: =+SUMIF('📁 Panel CMF'!$D$3:$D$93,'🏦 Agregados CMF'!A5,'📁 Panel CMF'!$E$3:$E$93) -> 248405.1 | D5: =0.3776*C5 -> 93797.766 | E5: =+C5-D5 -> 154607.33 | F5: =+SUMIF('📁 Panel CMF'!$D$3:$D$93,'🏦 Agregados CMF'!A5,'📁 Panel CMF'!$H$3:$H$93) -> 58544.8 | G5: =+E5-F5 -> 96062.534 | H5: =+SUMIF('📁 Panel CMF'!$D$3:$D$93,'🏦 Agregados CMF'!A5,'📁 Panel CMF'!$J$3:$J$93) -> 23293.4 | I5: =+F5/E5 -> 0.37866768 | J5: 144706000 | K5: =+(E5/J5)*100 -> 0.10684238
A6: 2015 | B6: =+COUNTIF('📁 Panel CMF'!$D$3:$D$93,'🏦 Agregados CMF'!A6) -> 7 | C6: =+SUMIF('📁 Panel CMF'!$D$3:$D$93,'🏦 Agregados CMF'!A6,'📁 Panel CMF'!$E$3:$E$93) -> 253822 | D6: =0.3776*C6 -> 95843.187 | E6: =+C6-D6 -> 157978.81 | F6: =+SUMIF('📁 Panel CMF'!$D$3:$D$93,'🏦 Agregados CMF'!A6,'📁 Panel CMF'!$H$3:$H$93) -> 63039.1 | G6: =+E6-F6 -> 94939.713 | H6: =+SUMIF('📁 Panel CMF'!$D$3:$D$93,'🏦 Agregados CMF'!A6,'📁 Panel CMF'!$J$3:$J$93) -> 35676.7 | I6: =+F6/E6 -> 0.39903515 | J6: 158623000 | K6: =+(E6/J6)*100 -> 0.099593888
A7: 2016 | B7: =+COUNTIF('📁 Panel CMF'!$D$3:$D$93,'🏦 Agregados CMF'!A7) -> 7 | C7: =+SUMIF('📁 Panel CMF'!$D$3:$D$93,'🏦 Agregados CMF'!A7,'📁 Panel CMF'!$E$3:$E$93) -> 268230.9 | D7: =0.3776*C7 -> 101283.99 | E7: =+C7-D7 -> 166946.91 | F7: =+SUMIF('📁 Panel CMF'!$D$3:$D$93,'🏦 Agregados CMF'!A7,'📁 Panel CMF'!$H$3:$H$93) -> 70127.7 | G7: =+E7-F7 -> 96819.212 | H7: =+SUMIF('📁 Panel CMF'!$D$3:$D$93,'🏦 Agregados CMF'!A7,'📁 Panel CMF'!$J$3:$J$93) -> 47670.3 | I7: =+F7/E7 -> 0.42005988 | J7: 168765000 | K7: =+(E7/J7)*100 -> 0.09892271
A8: 2017 | B8: =+COUNTIF('📁 Panel CMF'!$D$3:$D$93,'🏦 Agregados CMF'!A8) -> 7 | C8: =+SUMIF('📁 Panel CMF'!$D$3:$D$93,'🏦 Agregados CMF'!A8,'📁 Panel CMF'!$E$3:$E$93) -> 242779 | D8: =0.3776*C8 -> 91673.35 | E8: =+C8-D8 -> 151105.65 | F8: =+SUMIF('📁 Panel CMF'!$D$3:$D$93,'🏦 Agregados CMF'!A8,'📁 Panel CMF'!$H$3:$H$93) -> 73823 | G8: =+E8-F8 -> 77282.65 | H8: =+SUMIF('📁 Panel CMF'!$D$3:$D$93,'🏦 Agregados CMF'!A8,'📁 Panel CMF'!$J$3:$J$93) -> 67971 | I8: =+F8/E8 -> 0.48855222 | J8: 179315000 | K8: =+(E8/J8)*100 -> 0.084268271
A9: 2018 | B9: =+COUNTIF('📁 Panel CMF'!$D$3:$D$93,'🏦 Agregados CMF'!A9) -> 7 | C9: =+SUMIF('📁 Panel CMF'!$D$3:$D$93,'🏦 Agregados CMF'!A9,'📁 Panel CMF'!$E$3:$E$93) -> 257678 | D9: =0.3776*C9 -> 97299.213 | E9: =+C9-D9 -> 160378.79 | F9: =+SUMIF('📁 Panel CMF'!$D$3:$D$93,'🏦 Agregados CMF'!A9,'📁 Panel CMF'!$H$3:$H$93) -> 77911 | G9: =+E9-F9 -> 82467.787 | H9: =+SUMIF('📁 Panel CMF'!$D$3:$D$93,'🏦 Agregados CMF'!A9,'📁 Panel CMF'!$J$3:$J$93) -> 75638 | I9: =+F9/E9 -> 0.48579367 | J9: 189435000 | K9: =+(E9/J9)*100 -> 0.084661645
A10: 2019 | B10: =+COUNTIF('📁 Panel CMF'!$D$3:$D$93,'🏦 Agregados CMF'!A10) -> 7 | C10: =+SUMIF('📁 Panel CMF'!$D$3:$D$93,'🏦 Agregados CMF'!A10,'📁 Panel CMF'!$E$3:$E$93) -> 277718 | D10: =0.3776*C10 -> 104866.32 | E10: =+C10-D10 -> 172851.68 | F10: =+SUMIF('📁 Panel CMF'!$D$3:$D$93,'🏦 Agregados CMF'!A10,'📁 Panel CMF'!$H$3:$H$93) -> 83157 | G10: =+E10-F10 -> 89694.683 | H10: =+SUMIF('📁 Panel CMF'!$D$3:$D$93,'🏦 Agregados CMF'!A10,'📁 Panel CMF'!$J$3:$J$93) -> 78686 | I10: =+F10/E10 -> 0.48108875 | J10: 195548000 | K10: =+(E10/J10)*100 -> 0.08839348
A11: 2020 | B11: =+COUNTIF('📁 Panel CMF'!$D$3:$D$93,'🏦 Agregados CMF'!A11) -> 7 | C11: =+SUMIF('📁 Panel CMF'!$D$3:$D$93,'🏦 Agregados CMF'!A11,'📁 Panel CMF'!$E$3:$E$93) -> 269886 | D11: =0.3776*C11 -> 101908.95 | E11: =+C11-D11 -> 167977.05 | F11: =+SUMIF('📁 Panel CMF'!$D$3:$D$93,'🏦 Agregados CMF'!A11,'📁 Panel CMF'!$H$3:$H$93) -> 87279 | G11: =+E11-F11 -> 80698.046 | H11: =+SUMIF('📁 Panel CMF'!$D$3:$D$93,'🏦 Agregados CMF'!A11,'📁 Panel CMF'!$J$3:$J$93) -> 67319 | I11: =+F11/E11 -> 0.51958885 | J11: 201307000 | K11: =+(E11/J11)*100 -> 0.083443222
A12: 2021 | B12: =+COUNTIF('📁 Panel CMF'!$D$3:$D$93,'🏦 Agregados CMF'!A12) -> 7 | C12: =+SUMIF('📁 Panel CMF'!$D$3:$D$93,'🏦 Agregados CMF'!A12,'📁 Panel CMF'!$E$3:$E$93) -> 275612 | D12: =0.3776*C12 -> 104071.09 | E12: =+C12-D12 -> 171540.91 | F12: =+SUMIF('📁 Panel CMF'!$D$3:$D$93,'🏦 Agregados CMF'!A12,'📁 Panel CMF'!$H$3:$H$93) -> 88696 | G12: =+E12-F12 -> 82844.909 | H12: =+SUMIF('📁 Panel CMF'!$D$3:$D$93,'🏦 Agregados CMF'!A12,'📁 Panel CMF'!$J$3:$J$93) -> 99711 | I12: =+F12/E12 -> 0.51705451 | J12: 239556000 | K12: =+(E12/J12)*100 -> 0.071607853
A13: 2022 | B13: =+COUNTIF('📁 Panel CMF'!$D$3:$D$93,'🏦 Agregados CMF'!A13) -> 7 | C13: =+SUMIF('📁 Panel CMF'!$D$3:$D$93,'🏦 Agregados CMF'!A13,'📁 Panel CMF'!$E$3:$E$93) -> 339948 | D13: =0.3776*C13 -> 128364.36 | E13: =+C13-D13 -> 211583.64 | F13: =+SUMIF('📁 Panel CMF'!$D$3:$D$93,'🏦 Agregados CMF'!A13,'📁 Panel CMF'!$H$3:$H$93) -> 91779.8 | G13: =+E13-F13 -> 119803.84 | H13: =+SUMIF('📁 Panel CMF'!$D$3:$D$93,'🏦 Agregados CMF'!A13,'📁 Panel CMF'!$J$3:$J$93) -> 128122 | I13: =+F13/E13 -> 0.43377551 | J13: 262954000 | K13: =+(E13/J13)*100 -> 0.080464125
A14: 2023 | B14: =+COUNTIF('📁 Panel CMF'!$D$3:$D$93,'🏦 Agregados CMF'!A14) -> 7 | C14: =+SUMIF('📁 Panel CMF'!$D$3:$D$93,'🏦 Agregados CMF'!A14,'📁 Panel CMF'!$E$3:$E$93) -> 337614 | D14: =0.3776*C14 -> 127483.05 | E14: =+C14-D14 -> 210130.95 | F14: =+SUMIF('📁 Panel CMF'!$D$3:$D$93,'🏦 Agregados CMF'!A14,'📁 Panel CMF'!$H$3:$H$93) -> 92726.6 | G14: =+E14-F14 -> 117404.35 | H14: =+SUMIF('📁 Panel CMF'!$D$3:$D$93,'🏦 Agregados CMF'!A14,'📁 Panel CMF'!$J$3:$J$93) -> 92033 | I14: =+F14/E14 -> 0.44128006 | J14: 282097000 | K14: =+(E14/J14)*100 -> 0.0744889
A15: 2024 | B15: =+COUNTIF('📁 Panel CMF'!$D$3:$D$93,'🏦 Agregados CMF'!A15) -> 7 | C15: =+SUMIF('📁 Panel CMF'!$D$3:$D$93,'🏦 Agregados CMF'!A15,'📁 Panel CMF'!$E$3:$E$93) -> 404738 | D15: =0.3776*C15 -> 152829.07 | E15: =+C15-D15 -> 251908.93 | F15: =+SUMIF('📁 Panel CMF'!$D$3:$D$93,'🏦 Agregados CMF'!A15,'📁 Panel CMF'!$H$3:$H$93) -> 109310 | G15: =+E15-F15 -> 142598.93 | H15: =+SUMIF('📁 Panel CMF'!$D$3:$D$93,'🏦 Agregados CMF'!A15,'📁 Panel CMF'!$J$3:$J$93) -> 101974 | I15: =+F15/E15 -> 0.43392666 | J15: 310681000 | K15: =+(E15/J15)*100 -> 0.081082825
A16: 2025 | B16: =+COUNTIF('📁 Panel CMF'!$D$3:$D$93,'🏦 Agregados CMF'!A16) -> 7 | C16: =+SUMIF('📁 Panel CMF'!$D$3:$D$93,'🏦 Agregados CMF'!A16,'📁 Panel CMF'!$E$3:$E$93) -> 445885 | D16: =0.3776*C16 -> 168366.18 | E16: =+C16-D16 -> 277518.82 | F16: =+SUMIF('📁 Panel CMF'!$D$3:$D$93,'🏦 Agregados CMF'!A16,'📁 Panel CMF'!$H$3:$H$93) -> 122763.2 | G16: =+E16-F16 -> 154755.62 | H16: =+SUMIF('📁 Panel CMF'!$D$3:$D$93,'🏦 Agregados CMF'!A16,'📁 Panel CMF'!$J$3:$J$93) -> 108265 | I16: =+F16/E16 -> 0.4423599 | J16: 339978000 | K16: =+(E16/J16)*100 -> 0.081628465
A17: TOTAL PERÍODO | C17: =+SUM(C4:C16) -> 3882791 | D17: =+SUM(D4:D16) -> 1466141.9 | E17: =+SUM(E4:E16) -> 2416649.1 | F17: =+SUM(F4:F16) -> 1081034.5 | G17: =+SUM(G4:G16) -> 1335614.6 | H17: =+SUM(H4:H16) -> 949227.8 | I17: — | J17: —
A21: CUENTA FINANCIERA — BALANCE GENERAL
A22: F2 = Depósitos captados (vista + plazo) | F4 = Colocaciones netas (total − provisiones)
A23: Año | B23: N | C23: Activos (MM$) | D23: Patrimonio (MM$) | E23: F2 Depósitos (MM$) | F23: F4 Colocaciones (MM$) | G23: F4/Activos | H23: F2/Activos
A24: 2013 | B24: =+COUNTIF('📁 Panel CMF'!$D$3:$D$93,'🏦 Agregados CMF'!A24) -> 7 | C24: =+SUMIF('📁 Panel CMF'!$D$3:$D$93,'🏦 Agregados CMF'!A24,'📁 Panel CMF'!$M$3:$M$93) -> 1434093.4 | D24: =+SUMIF('📁 Panel CMF'!$D$3:$D$93,'🏦 Agregados CMF'!A24,'📁 Panel CMF'!$N$3:$N$93) -> 439510.7 | E24: =+SUMIF('📁 Panel CMF'!$D$3:$D$93,'🏦 Agregados CMF'!A24,'📁 Panel CMF'!$K$3:$K$93) -> 709177.9 | F24: =+SUMIF('📁 Panel CMF'!$D$3:$D$93,'🏦 Agregados CMF'!A24,'📁 Panel CMF'!$L$3:$L$93) -> 1274441.1 | G24: =+F24/C24 -> 0.88867371 | H24: =+E24/C24 -> 0.49451305
A25: 2014 | B25: =+COUNTIF('📁 Panel CMF'!$D$3:$D$93,'🏦 Agregados CMF'!A25) -> 7 | C25: =+SUMIF('📁 Panel CMF'!$D$3:$D$93,'🏦 Agregados CMF'!A25,'📁 Panel CMF'!$M$3:$M$93) -> 1432048 | D25: =+SUMIF('📁 Panel CMF'!$D$3:$D$93,'🏦 Agregados CMF'!A25,'📁 Panel CMF'!$N$3:$N$93) -> 449722.7 | E25: =+SUMIF('📁 Panel CMF'!$D$3:$D$93,'🏦 Agregados CMF'!A25,'📁 Panel CMF'!$K$3:$K$93) -> 716124.9 | F25: =+SUMIF('📁 Panel CMF'!$D$3:$D$93,'🏦 Agregados CMF'!A25,'📁 Panel CMF'!$L$3:$L$93) -> 1266778.5 | G25: =+F25/C25 -> 0.88459221 | H25: =+E25/C25 -> 0.50007046
A26: 2015 | B26: =+COUNTIF('📁 Panel CMF'!$D$3:$D$93,'🏦 Agregados CMF'!A26) -> 7 | C26: =+SUMIF('📁 Panel CMF'!$D$3:$D$93,'🏦 Agregados CMF'!A26,'📁 Panel CMF'!$M$3:$M$93) -> 1529424.5 | D26: =+SUMIF('📁 Panel CMF'!$D$3:$D$93,'🏦 Agregados CMF'!A26,'📁 Panel CMF'!$N$3:$N$93) -> 491407.2 | E26: =+SUMIF('📁 Panel CMF'!$D$3:$D$93,'🏦 Agregados CMF'!A26,'📁 Panel CMF'!$K$3:$K$93) -> 742253.9 | F26: =+SUMIF('📁 Panel CMF'!$D$3:$D$93,'🏦 Agregados CMF'!A26,'📁 Panel CMF'!$L$3:$L$93) -> 1331001.7 | G26: =+F26/C26 -> 0.8702631 | H26: =+E26/C26 -> 0.48531582
A27: 2016 | B27: =+COUNTIF('📁 Panel CMF'!$D$3:$D$93,'🏦 Agregados CMF'!A27) -> 7 | C27: =+SUMIF('📁 Panel CMF'!$D$3:$D$93,'🏦 Agregados CMF'!A27,'📁 Panel CMF'!$M$3:$M$93) -> 1666467.7 | D27: =+SUMIF('📁 Panel CMF'!$D$3:$D$93,'🏦 Agregados CMF'!A27,'📁 Panel CMF'!$N$3:$N$93) -> 533773.4 | E27: =+SUMIF('📁 Panel CMF'!$D$3:$D$93,'🏦 Agregados CMF'!A27,'📁 Panel CMF'!$K$3:$K$93) -> 845168.9 | F27: =+SUMIF('📁 Panel CMF'!$D$3:$D$93,'🏦 Agregados CMF'!A27,'📁 Panel CMF'!$L$3:$L$93) -> 1417495.1 | G27: =+F27/C27 -> 0.8505986 | H27: =+E27/C27 -> 0.50716188
A28: 2017 | B28: =+COUNTIF('📁 Panel CMF'!$D$3:$D$93,'🏦 Agregados CMF'!A28) -> 7 | C28: =+SUMIF('📁 Panel CMF'!$D$3:$D$93,'🏦 Agregados CMF'!A28,'📁 Panel CMF'!$M$3:$M$93) -> 1810978 | D28: =+SUMIF('📁 Panel CMF'!$D$3:$D$93,'🏦 Agregados CMF'!A28,'📁 Panel CMF'!$N$3:$N$93) -> 510013 | E28: =+SUMIF('📁 Panel CMF'!$D$3:$D$93,'🏦 Agregados CMF'!A28,'📁 Panel CMF'!$K$3:$K$93) -> 849926 | F28: =+SUMIF('📁 Panel CMF'!$D$3:$D$93,'🏦 Agregados CMF'!A28,'📁 Panel CMF'!$L$3:$L$93) -> 1563136 | G28: =+F28/C28 -> 0.86314467 | H28: =+E28/C28 -> 0.46931879
A29: 2018 | B29: =+COUNTIF('📁 Panel CMF'!$D$3:$D$93,'🏦 Agregados CMF'!A29) -> 7 | C29: =+SUMIF('📁 Panel CMF'!$D$3:$D$93,'🏦 Agregados CMF'!A29,'📁 Panel CMF'!$M$3:$M$93) -> 1981664 | D29: =+SUMIF('📁 Panel CMF'!$D$3:$D$93,'🏦 Agregados CMF'!A29,'📁 Panel CMF'!$N$3:$N$93) -> 538757 | E29: =+SUMIF('📁 Panel CMF'!$D$3:$D$93,'🏦 Agregados CMF'!A29,'📁 Panel CMF'!$K$3:$K$93) -> 925938 | F29: =+SUMIF('📁 Panel CMF'!$D$3:$D$93,'🏦 Agregados CMF'!A29,'📁 Panel CMF'!$L$3:$L$93) -> 1669836 | G29: =+F29/C29 -> 0.84264335 | H29: =+E29/C29 -> 0.46725277
A30: 2019 | B30: =+COUNTIF('📁 Panel CMF'!$D$3:$D$93,'🏦 Agregados CMF'!A30) -> 7 | C30: =+SUMIF('📁 Panel CMF'!$D$3:$D$93,'🏦 Agregados CMF'!A30,'📁 Panel CMF'!$M$3:$M$93) -> 2196438 | D30: =+SUMIF('📁 Panel CMF'!$D$3:$D$93,'🏦 Agregados CMF'!A30,'📁 Panel CMF'!$N$3:$N$93) -> 577075 | E30: =+SUMIF('📁 Panel CMF'!$D$3:$D$93,'🏦 Agregados CMF'!A30,'📁 Panel CMF'!$K$3:$K$93) -> 1046676 | F30: =+SUMIF('📁 Panel CMF'!$D$3:$D$93,'🏦 Agregados CMF'!A30,'📁 Panel CMF'!$L$3:$L$93) -> 1816557 | G30: =+F30/C30 -> 0.82704679 | H30: =+E30/C30 -> 0.47653337
A31: 2020 | B31: =+COUNTIF('📁 Panel CMF'!$D$3:$D$93,'🏦 Agregados CMF'!A31) -> 7 | C31: =+SUMIF('📁 Panel CMF'!$D$3:$D$93,'🏦 Agregados CMF'!A31,'📁 Panel CMF'!$M$3:$M$93) -> 2539812 | D31: =+SUMIF('📁 Panel CMF'!$D$3:$D$93,'🏦 Agregados CMF'!A31,'📁 Panel CMF'!$N$3:$N$93) -> 622202 | E31: =+SUMIF('📁 Panel CMF'!$D$3:$D$93,'🏦 Agregados CMF'!A31,'📁 Panel CMF'!$K$3:$K$93) -> 1335887 | F31: =+SUMIF('📁 Panel CMF'!$D$3:$D$93,'🏦 Agregados CMF'!A31,'📁 Panel CMF'!$L$3:$L$93) -> 1845854 | G31: =+F31/C31 -> 0.72676797 | H31: =+E31/C31 -> 0.52597869
A32: 2021 | B32: =+COUNTIF('📁 Panel CMF'!$D$3:$D$93,'🏦 Agregados CMF'!A32) -> 7 | C32: =+SUMIF('📁 Panel CMF'!$D$3:$D$93,'🏦 Agregados CMF'!A32,'📁 Panel CMF'!$M$3:$M$93) -> 2839874 | D32: =+SUMIF('📁 Panel CMF'!$D$3:$D$93,'🏦 Agregados CMF'!A32,'📁 Panel CMF'!$N$3:$N$93) -> 662605 | E32: =+SUMIF('📁 Panel CMF'!$D$3:$D$93,'🏦 Agregados CMF'!A32,'📁 Panel CMF'!$K$3:$K$93) -> 1672418 | F32: =+SUMIF('📁 Panel CMF'!$D$3:$D$93,'🏦 Agregados CMF'!A32,'📁 Panel CMF'!$L$3:$L$93) -> 1927331 | G32: =+F32/C32 -> 0.67866779 | H32: =+E32/C32 -> 0.5889057
A33: 2022 | B33: =+COUNTIF('📁 Panel CMF'!$D$3:$D$93,'🏦 Agregados CMF'!A33) -> 7 | C33: =+SUMIF('📁 Panel CMF'!$D$3:$D$93,'🏦 Agregados CMF'!A33,'📁 Panel CMF'!$M$3:$M$93) -> 3148866 | D33: =+SUMIF('📁 Panel CMF'!$D$3:$D$93,'🏦 Agregados CMF'!A33,'📁 Panel CMF'!$N$3:$N$93) -> 754875 | E33: =+SUMIF('📁 Panel CMF'!$D$3:$D$93,'🏦 Agregados CMF'!A33,'📁 Panel CMF'!$K$3:$K$93) -> 1851317 | F33: =+SUMIF('📁 Panel CMF'!$D$3:$D$93,'🏦 Agregados CMF'!A33,'📁 Panel CMF'!$L$3:$L$93) -> 2320141 | G33: =+F33/C33 -> 0.73681795 | H33: =+E33/C33 -> 0.58793134
A34: 2023 | B34: =+COUNTIF('📁 Panel CMF'!$D$3:$D$93,'🏦 Agregados CMF'!A34) -> 7 | C34: =+SUMIF('📁 Panel CMF'!$D$3:$D$93,'🏦 Agregados CMF'!A34,'📁 Panel CMF'!$M$3:$M$93) -> 3570911 | D34: =+SUMIF('📁 Panel CMF'!$D$3:$D$93,'🏦 Agregados CMF'!A34,'📁 Panel CMF'!$N$3:$N$93) -> 780738 | E34: =+SUMIF('📁 Panel CMF'!$D$3:$D$93,'🏦 Agregados CMF'!A34,'📁 Panel CMF'!$K$3:$K$93) -> 2227089 | F34: =+SUMIF('📁 Panel CMF'!$D$3:$D$93,'🏦 Agregados CMF'!A34,'📁 Panel CMF'!$L$3:$L$93) -> 2709167 | G34: =+F34/C34 -> 0.75867671 | H34: =+E34/C34 -> 0.6236753
A35: 2024 | B35: =+COUNTIF('📁 Panel CMF'!$D$3:$D$93,'🏦 Agregados CMF'!A35) -> 7 | C35: =+SUMIF('📁 Panel CMF'!$D$3:$D$93,'🏦 Agregados CMF'!A35,'📁 Panel CMF'!$M$3:$M$93) -> 4056784 | D35: =+SUMIF('📁 Panel CMF'!$D$3:$D$93,'🏦 Agregados CMF'!A35,'📁 Panel CMF'!$N$3:$N$93) -> 862532 | E35: =+SUMIF('📁 Panel CMF'!$D$3:$D$93,'🏦 Agregados CMF'!A35,'📁 Panel CMF'!$K$3:$K$93) -> 2536374 | F35: =+SUMIF('📁 Panel CMF'!$D$3:$D$93,'🏦 Agregados CMF'!A35,'📁 Panel CMF'!$L$3:$L$93) -> 3042152 | G35: =+F35/C35 -> 0.74989253 | H35: =+E35/C35 -> 0.62521791
A36: 2025 | B36: =+COUNTIF('📁 Panel CMF'!$D$3:$D$93,'🏦 Agregados CMF'!A36) -> 7 | C36: =+SUMIF('📁 Panel CMF'!$D$3:$D$93,'🏦 Agregados CMF'!A36,'📁 Panel CMF'!$M$3:$M$93) -> 4481909 | D36: =+SUMIF('📁 Panel CMF'!$D$3:$D$93,'🏦 Agregados CMF'!A36,'📁 Panel CMF'!$N$3:$N$93) -> 915240 | E36: =+SUMIF('📁 Panel CMF'!$D$3:$D$93,'🏦 Agregados CMF'!A36,'📁 Panel CMF'!$K$3:$K$93) -> 2761339 | F36: =+SUMIF('📁 Panel CMF'!$D$3:$D$93,'🏦 Agregados CMF'!A36,'📁 Panel CMF'!$L$3:$L$93) -> 3369182 | G36: =+F36/C36 -> 0.75172923 | H36: =+E36/C36 -> 0.61610778
A37: TOTAL PERÍODO | C37: =+SUM(C24:C36) -> 32689270 | D37: =+SUM(D24:D36) -> 8138451 | E37: =+SUM(E24:E36) -> 18219690 | F37: =+SUM(F24:F36) -> 25553072 | G37: — | H37: —

Sheet 🏦 Agregado Total
A1: CUENTA DE PRODUCCIÓN Y GENERACIÓN DEL INGRESO TOTAL — CMF + DAES
A2: P2 = α×P1 (α=0,3776) | B1g = P1−P2 | PIB: Banco Central ref. 2018
A3: Año | B3: N | C3: P1 (MM$) | D3: P2 (MM$) | E3: B1g (MM$) | F3: D1 (MM$) | G3: B2g (MM$) | H3: Rem (MM$) | I3: D1/B1g | J3: PIB Chile (MM$) | K3: Aporte (%)
A4: 2013 | B4: 7 | C4: =+SUMIF('📁 Panel CMF'!$D$3:$D$93,'🏦 Agregados CMF'!A4,'📁 Panel CMF'!$E$3:$E$93) -> 260475 | D4: =0.3776*C4 -> 98355.36 | E4: =+C4-D4 -> 162119.64 | F4: =+SUMIF('📁 Panel CMF'!$D$3:$D$93,'🏦 Agregados CMF'!A4,'📁 Panel CMF'!$H$3:$H$93) -> 61877.3 | G4: =+E4-F4 -> 100242.34 | H4: =+SUMIF('📁 Panel CMF'!$D$3:$D$93,'🏦 Agregados CMF'!A4,'📁 Panel CMF'!$J$3:$J$93) -> 22868.4 | I4: =+F4/E4 -> 0.38167677 | J4: 136003000 | K4: =+(E4/J4)*100 -> 0.11920299
A5: 2014 | B5: =+'📊 Agregados DAES'!B4+'🏦 Agregados CMF'!B5 -> 9 | C5: =+'🏦 Agregados CMF'!C5+'📊 Agregados DAES'!C4 -> 248652.99 | D5: =0.3776*C5 -> 93891.37 | E5: =+C5-D5 -> 154761.62 | F5: =+'🏦 Agregados CMF'!F5+'📊 Agregados DAES'!F4 -> 58623.024 | G5: =+E5-F5 -> 96138.599 | H5: =+'📊 Agregados DAES'!H4+'🏦 Agregados CMF'!H5 -> 23286.547 | I5: =+F5/E5 -> 0.37879561 | J5: 144706000 | K5: =+(E5/J5)*100 -> 0.106949
A6: 2015 | B6: =+'📊 Agregados DAES'!B5+'🏦 Agregados CMF'!B6 -> 14 | C6: =+'🏦 Agregados CMF'!C6+'📊 Agregados DAES'!C5 -> 259248.06 | D6: =0.3776*C6 -> 97892.069 | E6: =+C6-D6 -> 161356 | F6: =+'🏦 Agregados CMF'!F6+'📊 Agregados DAES'!F5 -> 64801.916 | G6: =+E6-F6 -> 96554.079 | H6: =+'📊 Agregados DAES'!H5+'🏦 Agregados CMF'!H6 -> 36417.303 | I6: =+F6/E6 -> 0.40160835 | J6: 158623000 | K6: =+(E6/J6)*100 -> 0.10172295
A7: 2016 | B7: =+'📊 Agregados DAES'!B6+'🏦 Agregados CMF'!B7 -> 16 | C7: =+'🏦 Agregados CMF'!C7+'📊 Agregados DAES'!C6 -> 274314.14 | D7: =0.3776*C7 -> 103581.02 | E7: =+C7-D7 -> 170733.12 | F7: =+'🏦 Agregados CMF'!F7+'📊 Agregados DAES'!F6 -> 72127.976 | G7: =+E7-F7 -> 98605.142 | H7: =+'📊 Agregados DAES'!H6+'🏦 Agregados CMF'!H7 -> 48020.756 | I7: =+F7/E7 -> 0.42246037 | J7: 168765000 | K7: =+(E7/J7)*100 -> 0.10116619
A8: 2017 | B8: =+'📊 Agregados DAES'!B7+'🏦 Agregados CMF'!B8 -> 19 | C8: =+'🏦 Agregados CMF'!C8+'📊 Agregados DAES'!C7 -> 249003.25 | D8: =0.3776*C8 -> 94023.626 | E8: =+C8-D8 -> 154979.62 | F8: =+'🏦 Agregados CMF'!F8+'📊 Agregados DAES'!F7 -> 76445.225 | G8: =+E8-F8 -> 78534.396 | H8: =+'📊 Agregados DAES'!H7+'🏦 Agregados CMF'!H8 -> 68231.277 | I8: =+F8/E8 -> 0.49325985 | J8: 179315000 | K8: =+(E8/J8)*100 -> 0.086428699
A9: 2018 | B9: =+'📊 Agregados DAES'!B8+'🏦 Agregados CMF'!B9 -> 21 | C9: =+'🏦 Agregados CMF'!C9+'📊 Agregados DAES'!C8 -> 266655.26 | D9: =0.3776*C9 -> 100689.03 | E9: =+C9-D9 -> 165966.23 | F9: =+'🏦 Agregados CMF'!F9+'📊 Agregados DAES'!F8 -> 82296.242 | G9: =+E9-F9 -> 83669.992 | H9: =+'📊 Agregados DAES'!H8+'🏦 Agregados CMF'!H9 -> 76266.357 | I9: =+F9/E9 -> 0.49586135 | J9: 189435000 | K9: =+(E9/J9)*100 -> 0.087611177
A10: 2019 | B10: =+'📊 Agregados DAES'!B9+'🏦 Agregados CMF'!B10 -> 13 | C10: =+'🏦 Agregados CMF'!C10+'📊 Agregados DAES'!C9 -> 282385.25 | D10: =0.3776*C10 -> 106628.67 | E10: =+C10-D10 -> 175756.58 | F10: =+'🏦 Agregados CMF'!F10+'📊 Agregados DAES'!F9 -> 85011.988 | G10: =+E10-F10 -> 90744.593 | H10: =+'📊 Agregados DAES'!H9+'🏦 Agregados CMF'!H10 -> 79189.367 | I10: =+F10/E10 -> 0.48369163 | J10: 195548000 | K10: =+(E10/J10)*100 -> 0.089878997
A11: 2020 | B11: =+'📊 Agregados DAES'!B10+'🏦 Agregados CMF'!B11 -> 17 | C11: =+'🏦 Agregados CMF'!C11+'📊 Agregados DAES'!C10 -> 276050.64 | D11: =0.3776*C11 -> 104236.72 | E11: =+C11-D11 -> 171813.92 | F11: =+'🏦 Agregados CMF'!F11+'📊 Agregados DAES'!F10 -> 89698.905 | G11: =+E11-F11 -> 82115.011 | H11: =+'📊 Agregados DAES'!H10+'🏦 Agregados CMF'!H11 -> 67474.049 | I11: =+F11/E11 -> 0.52207008 | J11: 201307000 | K11: =+(E11/J11)*100 -> 0.085349201
A12: 2021 | B12: =+'📊 Agregados DAES'!B11+'🏦 Agregados CMF'!B12 -> 17 | C12: =+'🏦 Agregados CMF'!C12+'📊 Agregados DAES'!C11 -> 281622.52 | D12: =0.3776*C12 -> 106340.66 | E12: =+C12-D12 -> 175281.86 | F12: =+'🏦 Agregados CMF'!F12+'📊 Agregados DAES'!F11 -> 90726.023 | G12: =+E12-F12 -> 84555.833 | H12: =+'📊 Agregados DAES'!H11+'🏦 Agregados CMF'!H12 -> 99740.252 | I12: =+F12/E12 -> 0.51760077 | J12: 239556000 | K12: =+(E12/J12)*100 -> 0.07316947
A13: 2022 | B13: =+'📊 Agregados DAES'!B12+'🏦 Agregados CMF'!B13 -> 26 | C13: =+'🏦 Agregados CMF'!C13+'📊 Agregados DAES'!C12 -> 362119.99 | D13: =0.3776*C13 -> 136736.51 | E13: =+C13-D13 -> 225383.48 | F13: =+'🏦 Agregados CMF'!F13+'📊 Agregados DAES'!F12 -> 98747.172 | G13: =+E13-F13 -> 126636.31 | H13: =+'📊 Agregados DAES'!H12+'🏦 Agregados CMF'!H13 -> 125549.16 | I13: =+F13/E13 -> 0.43812959 | J13: 262954000 | K13: =+(E13/J13)*100 -> 0.085712132
A14: 2023 | B14: =+'📊 Agregados DAES'!B13+'🏦 Agregados CMF'!B14 -> 29 | C14: =+'🏦 Agregados CMF'!C14+'📊 Agregados DAES'!C13 -> 385018.63 | D14: =0.3776*C14 -> 145383.03 | E14: =+C14-D14 -> 239635.59 | F14: =+'🏦 Agregados CMF'!F14+'📊 Agregados DAES'!F13 -> 105308.98 | G14: =+E14-F14 -> 134326.61 | H14: =+'📊 Agregados DAES'!H13+'🏦 Agregados CMF'!H14 -> 94575.858 | I14: =+F14/E14 -> 0.43945469 | J14: 282097000 | K14: =+(E14/J14)*100 -> 0.084947941
A15: 2024 | B15: =+'📊 Agregados DAES'!B14+'🏦 Agregados CMF'!B15 -> 18 | C15: =+'🏦 Agregados CMF'!C15+'📊 Agregados DAES'!C14 -> 422873.86 | D15: =0.3776*C15 -> 159677.17 | E15: =+C15-D15 -> 263196.69 | F15: =+'🏦 Agregados CMF'!F15+'📊 Agregados DAES'!F14 -> 117579.45 | G15: =+E15-F15 -> 145617.24 | H15: =+'📊 Agregados DAES'!H14+'🏦 Agregados CMF'!H15 -> 104220.72 | I15: =+F15/E15 -> 0.44673604 | J15: 310681000 | K15: =+(E15/J15)*100 -> 0.084716056
A16: 2025 | B16: =+'📊 Agregados DAES'!B15+'🏦 Agregados CMF'!B16 -> 7 | C16: =+'🏦 Agregados CMF'!C16+'📊 Agregados DAES'!C15 -> 577398.59 | D16: =0.3776*C16 -> 218025.71 | E16: =+C16-D16 -> 359372.88 | F16: =+'🏦 Agregados CMF'!F16+'📊 Agregados DAES'!F15 -> 167736.1 | G16: =+E16-F16 -> 191636.78 | H16: =+'📊 Agregados DAES'!H15+'🏦 Agregados CMF'!H16 -> 113142.24 | I16: =+F16/E16 -> 0.46674669 | J16: 339978000 | K16: =+(E16/J16)*100 -> 0.10570475
A17: TOTAL PERÍODO | C17: =+SUM(C4:C16) -> 4145818.2 | D17: =+SUM(D4:D16) -> 1565460.9 | E17: =+SUM(E4:E16) -> 2580357.2 | F17: =+SUM(F4:F16) -> 1170980.3 | G17: =+SUM(G4:G16) -> 1409376.9 | H17: =+SUM(H4:H16) -> 958982.29 | I17: — | J17: —
A20: CUENTA FINANCIERA — BALANCE GENERAL TOTAL
A21: F2 = Depósitos captados (vista + plazo) | F4 = Colocaciones netas (total − provisiones)
A22: Año | B22: N | C22: Activos (MM$) | D22: Patrimonio (MM$) | E22: F2 Depósitos (MM$) | F22: F4 Colocaciones (MM$) | G22: F4/Activos | H22: F2/Activos
A23: 2013 | B23: =+'🏦 Agregados CMF'!B24 -> 7 | C23: =+'🏦 Agregados CMF'!C24 -> 1434093.4 | D23: =+'🏦 Agregados CMF'!D24 -> 439510.7 | E23: =+'🏦 Agregados CMF'!E24 -> 709177.9 | F23: =+'🏦 Agregados CMF'!F24 -> 1274441.1 | G23: =+F23/C23 -> 0.88867371 | H23: =+E23/C23 -> 0.49451305
A24: 2014 | B24: =+'📊 Agregados DAES'!B20+'🏦 Agregados CMF'!B25 -> 9 | C24: =+'📊 Agregados DAES'!C20+'🏦 Agregados CMF'!C25 -> 1433274.6 | D24: =+'📊 Agregados DAES'!D20+'🏦 Agregados CMF'!D25 -> 450855.22 | E24: =+'📊 Agregados DAES'!E20+'🏦 Agregados CMF'!E25 -> 716197.52 | F24: =+'📊 Agregados DAES'!F20+'🏦 Agregados CMF'!F25 -> 1267625.9 | G24: =+F24/C24 -> 0.88442637 | H24: =+E24/C24 -> 0.49969317
A25: 2015 | B25: =+COUNTIF('📁 Panel CMF'!$D$3:$D$93,'🏦 Agregados CMF'!A25) -> 7 | C25: =+'📊 Agregados DAES'!C21+'🏦 Agregados CMF'!C26 -> 1561464.4 | D25: =+'📊 Agregados DAES'!D21+'🏦 Agregados CMF'!D26 -> 518169.31 | E25: =+'📊 Agregados DAES'!E21+'🏦 Agregados CMF'!E26 -> 747250.56 | F25: =+'📊 Agregados DAES'!F21+'🏦 Agregados CMF'!F26 -> 1354989.9 | G25: =+F25/C25 -> 0.8677687 | H25: =+E25/C25 -> 0.47855755
A26: 2016 | B26: =+COUNTIF('📁 Panel CMF'!$D$3:$D$93,'🏦 Agregados CMF'!A26) -> 7 | C26: =+'📊 Agregados DAES'!C22+'🏦 Agregados CMF'!C27 -> 1676817.7 | D26: =+'📊 Agregados DAES'!D22+'🏦 Agregados CMF'!D27 -> 538454 | E26: =+'📊 Agregados DAES'!E22+'🏦 Agregados CMF'!E27 -> 850229.57 | F26: =+'📊 Agregados DAES'!F22+'🏦 Agregados CMF'!F27 -> 1424771.8 | G26: =+F26/C26 -> 0.84968795 | H26: =+E26/C26 -> 0.5070495
A27: 2017 | B27: =+COUNTIF('📁 Panel CMF'!$D$3:$D$93,'🏦 Agregados CMF'!A27) -> 7 | C27: =+'📊 Agregados DAES'!C23+'🏦 Agregados CMF'!C28 -> 1843430.6 | D27: =+'📊 Agregados DAES'!D23+'🏦 Agregados CMF'!D28 -> 527343.13 | E27: =+'📊 Agregados DAES'!E23+'🏦 Agregados CMF'!E28 -> 858659.34 | F27: =+'📊 Agregados DAES'!F23+'🏦 Agregados CMF'!F28 -> 1578414.4 | G27: =+F27/C27 -> 0.85623748 | H27: =+E27/C27 -> 0.46579423
A28: 2018 | B28: =+COUNTIF('📁 Panel CMF'!$D$3:$D$93,'🏦 Agregados CMF'!A28) -> 7 | C28: =+'📊 Agregados DAES'!C24+'🏦 Agregados CMF'!C29 -> 2033489.7 | D28: =+'📊 Agregados DAES'!D24+'🏦 Agregados CMF'!D29 -> 558139.34 | E28: =+'📊 Agregados DAES'!E24+'🏦 Agregados CMF'!E29 -> 938557.89 | F28: =+'📊 Agregados DAES'!F24+'🏦 Agregados CMF'!F29 -> 1699568.9 | G28: =+F28/C28 -> 0.83578931 | H28: =+E28/C28 -> 0.46155036
A29: 2019 | B29: =+COUNTIF('📁 Panel CMF'!$D$3:$D$93,'🏦 Agregados CMF'!A29) -> 7 | C29: =+'📊 Agregados DAES'!C25+'🏦 Agregados CMF'!C30 -> 2229477.7 | D29: =+'📊 Agregados DAES'!D25+'🏦 Agregados CMF'!D30 -> 591968.6 | E29: =+'📊 Agregados DAES'!E25+'🏦 Agregados CMF'!E30 -> 1062063.1 | F29: =+'📊 Agregados DAES'!F25+'🏦 Agregados CMF'!F30 -> 1840175.1 | G29: =+F29/C29 -> 0.82538393 | H29: =+E29/C29 -> 0.47637305
A30: 2020 | B30: =+COUNTIF('📁 Panel CMF'!$D$3:$D$93,'🏦 Agregados CMF'!A30) -> 7 | C30: =+'📊 Agregados DAES'!C26+'🏦 Agregados CMF'!C31 -> 2586910.7 | D30: =+'📊 Agregados DAES'!D26+'🏦 Agregados CMF'!D31 -> 645841.69 | E30: =+'📊 Agregados DAES'!E26+'🏦 Agregados CMF'!E31 -> 1357193.1 | F30: =+'📊 Agregados DAES'!F26+'🏦 Agregados CMF'!F31 -> 1873316.1 | G30: =+F30/C30 -> 0.72415181 | H30: =+E30/C30 -> 0.52463854
A31: 2021 | B31: =+COUNTIF('📁 Panel CMF'!$D$3:$D$93,'🏦 Agregados CMF'!A31) -> 7 | C31: =+'📊 Agregados DAES'!C27+'🏦 Agregados CMF'!C32 -> 2886670 | D31: =+'📊 Agregados DAES'!D27+'🏦 Agregados CMF'!D32 -> 687708.64 | E31: =+'📊 Agregados DAES'!E27+'🏦 Agregados CMF'!E32 -> 1692111.5 | F31: =+'📊 Agregados DAES'!F27+'🏦 Agregados CMF'!F32 -> 1955032.9 | G31: =+F31/C31 -> 0.67726234 | H31: =+E31/C31 -> 0.58618112
A32: 2022 | B32: =+COUNTIF('📁 Panel CMF'!$D$3:$D$93,'🏦 Agregados CMF'!A32) -> 7 | C32: =+'📊 Agregados DAES'!C28+'🏦 Agregados CMF'!C33 -> 3233454.7 | D32: =+'📊 Agregados DAES'!D28+'🏦 Agregados CMF'!D33 -> 801186.42 | E32: =+'📊 Agregados DAES'!E28+'🏦 Agregados CMF'!E33 -> 1885462.4 | F32: =+'📊 Agregados DAES'!F28+'🏦 Agregados CMF'!F33 -> 2376704.3 | G32: =+F32/C32 -> 0.73503559 | H32: =+E32/C32 -> 0.58311083
A33: 2023 | B33: =+COUNTIF('📁 Panel CMF'!$D$3:$D$93,'🏦 Agregados CMF'!A33) -> 7 | C33: =+'📊 Agregados DAES'!C29+'🏦 Agregados CMF'!C34 -> 3736816.3 | D33: =+'📊 Agregados DAES'!D29+'🏦 Agregados CMF'!D34 -> 852393.96 | E33: =+'📊 Agregados DAES'!E29+'🏦 Agregados CMF'!E34 -> 2314442.1 | F33: =+'📊 Agregados DAES'!F29+'🏦 Agregados CMF'!F34 -> 2823975.3 | G33: =+F33/C33 -> 0.75571691 | H33: =+E33/C33 -> 0.61936203
A34: 2024 | B34: =+COUNTIF('📁 Panel CMF'!$D$3:$D$93,'🏦 Agregados CMF'!A34) -> 7 | C34: =+'📊 Agregados DAES'!C30+'🏦 Agregados CMF'!C35 -> 4164706.7 | D34: =+'📊 Agregados DAES'!D30+'🏦 Agregados CMF'!D35 -> 906843.96 | E34: =+'📊 Agregados DAES'!E30+'🏦 Agregados CMF'!E35 -> 2596172.9 | F34: =+'📊 Agregados DAES'!F30+'🏦 Agregados CMF'!F35 -> 3123457 | G34: =+F34/C34 -> 0.74998247 | H34: =+E34/C34 -> 0.62337473
A35: 2025 | B35: =+COUNTIF('📁 Panel CMF'!$D$3:$D$93,'🏦 Agregados CMF'!A35) -> 7 | C35: =+'🏦 Agregados CMF'!C36 -> 4481909 | D35: =+'🏦 Agregados CMF'!D36 -> 915240 | E35: =+'🏦 Agregados CMF'!E36 -> 2761339 | F35: =+'🏦 Agregados CMF'!F36 -> 3369182 | G35: =+F35/C35 -> 0.75172923 | H35: =+E35/C35 -> 0.61610778
A36: TOTAL PERÍODO | C36: =+SUM(C23:C35) -> 33302515 | D36: =+SUM(D23:D35) -> 8433655 | E36: =+SUM(E23:E35) -> 18488857 | F36: =+SUM(F23:F35) -> 25961655 | G36: — | H36: —

Sheet 📁 Panel DAES
A1: PANEL DE DATOS — UNA FILA POR COOPERATIVA × AÑO
A2: Segmento | B2: Entidad | C2: RUT | D2: Año | E2: P1 (MM$) | F2: P2 (MM$) | G2: B1g (MM$) | H2: D1 (MM$) | I2: B2g (MM$) | J2: Rem (MM$) | K2: Activos (MM$) | L2: Patrimonio (MM$) | M2: F2 (MM$) | N2: F4 (MM$) | O2: PIB_MM | P2: Aporte (%)
A3: DAES | B3: Andescoop Ltda. | C3: 70009770-6 | D3: 2020 | E3: 1261.9174 | F3: =0.3776*E3 -> 476.50001 | G3: =+E3-F3 -> 785.41739 | H3: 644.20884 | I3: =+G3-H3 -> 141.20854 | J3: -311.96317 | K3: 12536.77 | L3: 6030.0445 | M3: 6454.2873 | N3: 4893.8679 | O3: 201307000 | P3: =+(G3/O3)*100 -> 0.000390159
A4: DAES | B4: Andescoop Ltda. | C4: 70009770-6 | D4: 2022 | E4: 1688.6546 | F4: =0.3776*E4 -> 637.63597 | G4: =+E4-F4 -> 1051.0186 | H4: 697.54668 | I4: =+G4-H4 -> 353.47193 | J4: -637.8462 | O4: 262954000 | P4: =+(G4/O4)*100 -> 0.00039969676
A5: DAES | B5: Andescoop Ltda. | C5: 70009770-6 | D5: 2023 | E5: 1972.1403 | F5: =0.3776*E5 -> 744.68018 | G5: =+E5-F5 -> 1227.4601 | H5: 774.03059 | I5: =+G5-H5 -> 453.42954 | J5: -144.99542 | O5: 282097000 | P5: =+(G5/O5)*100 -> 0.00043511988
A6: DAES | B6: Andescoop Ltda. | C6: 70009770-6 | D6: 2024 | E6: 1682.2219 | F6: =0.3776*E6 -> 635.20697 | G6: =+E6-F6 -> 1047.0149 | H6: 788.54711 | I6: =+G6-H6 -> 258.46777 | J6: 165.01095 | K6: 10789.782 | L6: 6508.7668 | M6: 4150.5813 | N6: 6057.262 | O6: 310681000 | P6: =+(G6/O6)*100 -> 0.00033700641
A7: DAES | B7: Coop. de Ahorro y Crédito Lautaro Rosas | C7: 70286300-7 | D7: 2016 | E7: 3715.6684 | F7: =0.3776*E7 -> 1403.0364 | G7: =+E7-F7 -> 2312.632 | H7: 1094.6625 | I7: =+G7-H7 -> 1217.9696 | J7: 244.33893 | O7: 168765000 | P7: =+(G7/O7)*100 -> 0.0013703268
A8: DAES | B8: Coop. de Ahorro, Crédito y Servicios Financie | C8: 85303300-6 | D8: 2023 | E8: 526.98993 | F8: =0.3776*E8 -> 198.9914 | G8: =+E8-F8 -> 327.99854 | I8: =+G8-H8 -> 327.99854 | J8: 273.25852 | K8: 3202.3398 | L8: 3126.2303 | N8: 2556.531 | O8: 282097000 | P8: =+(G8/O8)*100 -> 0.00011627154
A9: DAES | B9: Coop. de Ahorro, Crédito y Servicios Financie | C9: 85303300-6 | D9: 2024 | E9: 606.99092 | F9: =0.3776*E9 -> 229.19977 | G9: =+E9-F9 -> 377.79115 | I9: =+G9-H9 -> 377.79115 | J9: 312.94338 | K9: 3413.6621 | L9: 3347.5055 | N9: 2672.864 | O9: 310681000 | P9: =+(G9/O9)*100 -> 0.00012160098
A10: DAES | B10: Cooperativa de Ahorro y Crédito Ahorro Maule | C10: 83908800-0 | D10: 2016 | E10: 186.92499 | F10: =0.3776*E10 -> 70.582875 | G10: =+E10-F10 -> 116.34211 | H10: 114.67537 | I10: =+G10-H10 -> 1.6667395 | J10: 11.741258 | K10: 835.29859 | L10: 637.39627 | M10: 194.09069 | N10: 604.02813 | O10: 168765000 | P10: =+(G10/O10)*100 -> 6.8937346e-05
A11: DAES | B11: Cooperativa de Ahorro y Crédito Ahorro Maule | C11: 83908800-0 | D11: 2017 | E11: 200.52856 | F11: =0.3776*E11 -> 75.719585 | G11: =+E11-F11 -> 124.80898 | H11: 125.4804 | I11: =+G11-H11 -> -0.67142101 | J11: 15.889036 | K11: 897.25446 | L11: 671.75859 | M11: 219.71958 | N11: 672.72419 | O11: 179315000 | P11: =+(G11/O11)*100 -> 6.9603199e-05
A12: DAES | B12: Cooperativa de Ahorro y Crédito Ahorro Maule | C12: 83908800-0 | D12: 2018 | E12: 204.64546 | F12: =0.3776*E12 -> 77.274126 | G12: =+E12-F12 -> 127.37133 | H12: 129.35863 | I12: =+G12-H12 -> -1.9872977 | J12: 8.767605 | K12: 935.7158 | L12: 680.78947 | M12: 251.15994 | N12: 706.55119 | O12: 189435000 | P12: =+(G12/O12)*100 -> 6.7237487e-05
A13: DAES | B13: Cooperativa de Ahorro y Crédito Araucaniacoop | C13: 76489600-9 | D13: 2020 | E13: 324.92926 | F13: =0.3776*E13 -> 122.69329 | G13: =+E13-F13 -> 202.23597 | H13: 72.29985 | I13: =+G13-H13 -> 129.93612 | J13: 116.58819 | K13: 2690.7596 | L13: 1607.4387 | M13: 982.23502 | N13: 1532.5048 | O13: 201307000 | P13: =+(G13/O13)*100 -> 0.00010046147
A14: DAES | B14: Cooperativa de Ahorro y Crédito Araucaniacoop | C14: 76489600-9 | D14: 2021 | E14: 293.79417 | F14: =0.3776*E14 -> 110.93668 | G14: =+E14-F14 -> 182.85749 | H14: 73.823908 | I14: =+G14-H14 -> 109.03358 | J14: 6.158815 | K14: 3268.7477 | L14: 1681.1529 | M14: 1498.3962 | N14: 1187.013 | O14: 239556000 | P14: =+(G14/O14)*100 -> 7.6331835e-05
A15: DAES | B15: Cooperativa de Ahorro y Crédito Araucaniacoop | C15: 76489600-9 | D15: 2022 | E15: 349.90696 | F15: =0.3776*E15 -> 132.12487 | G15: =+E15-F15 -> 217.78209 | H15: 103.49862 | I15: =+G15-H15 -> 114.28347 | J15: -28.267172 | K15: 2819.4288 | L15: 1879.5437 | M15: 860.00942 | N15: 1929.4592 | O15: 262954000 | P15: =+(G15/O15)*100 -> 8.2821365e-05
A16: DAES | B16: Cooperativa de Ahorro y Crédito Araucaniacoop | C16: 76489600-9 | D16: 2022 | E16: 366.70249 | F16: =0.3776*E16 -> 138.46686 | G16: =+E16-F16 -> 228.23563 | H16: 108.46655 | I16: =+G16-H16 -> 119.76908 | J16: -29.623996 | K16: 2819.4288 | L16: 1879.5437 | M16: 860.00942 | N16: 1929.4592 | O16: 262954000 | P16: =+(G16/O16)*100 -> 8.679679e-05
A17: DAES | B17: Cooperativa de Ahorro y Crédito Araucaniacoop | C17: 76489600-9 | D17: 2023 | E17: 401.28502 | F17: =0.3776*E17 -> 151.52522 | G17: =+E17-F17 -> 249.7598 | H17: 133.80551 | I17: =+G17-H17 -> 115.95429 | J17: 57.804792 | O17: 282097000 | P17: =+(G17/O17)*100 -> 8.853685e-05
A18: DAES | B18: Cooperativa de Ahorro y Crédito Araucaniacoop | C18: 76489600-9 | D18: 2024 | E18: 418.51746 | F18: =0.3776*E18 -> 158.03219 | G18: =+E18-F18 -> 260.48527 | H18: 133.1766 | I18: =+G18-H18 -> 127.30867 | J18: 53.358415 | K18: 2970.091 | L18: 2139.1695 | M18: 783.46419 | N18: 1961.4377 | O18: 310681000 | P18: =+(G18/O18)*100 -> 8.3843321e-05
A19: DAES | B19: Cooperativa de Ahorro y Crédito Bancrece | C19: 65144029-7 | D19: 2021 | E19: 1.694809 | F19: =0.3776*E19 -> 0.63995988 | G19: =+E19-F19 -> 1.0548491 | I19: =+G19-H19 -> 1.0548491 | J19: -0.213368 | O19: 239556000 | P19: =+(G19/O19)*100 -> 4.4033509e-07
A20: DAES | B20: Cooperativa de Ahorro y Crédito Bancrece | C20: 65144029-7 | D20: 2022 | E20: 2.92309 | F20: =0.3776*E20 -> 1.1037588 | G20: =+E20-F20 -> 1.8193312 | H20: 1.282661 | I20: =+G20-H20 -> 0.53667022 | J20: -0.394412 | K20: 17.197674 | L20: 1.71025 | M20: 13.332883 | N20: 11.047155 | O20: 262954000 | P20: =+(G20/O20)*100 -> 6.9188193e-07
A21: DAES | B21: Cooperativa de Ahorro y Crédito Bancrece | C21: 65144029-7 | D21: 2023 | E21: 5.0178 | F21: =0.3776*E21 -> 1.8947213 | G21: =+E21-F21 -> 3.1230787 | H21: 1.543726 | I21: =+G21-H21 -> 1.5793527 | J21: 0.245738 | K21: 26.55487 | L21: 2.446476 | M21: 21.496 | N21: 18.202446 | O21: 282097000 | P21: =+(G21/O21)*100 -> 1.1070939e-06
A22: DAES | B22: Cooperativa de Ahorro y Crédito Bancrece | C22: 65144029-7 | D22: 2024 | E22: 8.197293 | F22: =0.3776*E22 -> 3.0952978 | G22: =+E22-F22 -> 5.1019952 | H22: 2.45793 | I22: =+G22-H22 -> 2.6440652 | J22: 1.167724 | K22: 42.551814 | L22: 4.076304 | M22: 37.214514 | N22: 32.154974 | O22: 310681000 | P22: =+(G22/O22)*100 -> 1.6421974e-06
A23: DAES | B23: Cooperativa de Ahorro y Crédito Bansur | C23: 65002821-K | D23: 2019 | E23: 1089.4257 | F23: =0.3776*E23 -> 411.36715 | G23: =+E23-F23 -> 678.05857 | H23: 352.76535 | I23: =+G23-H23 -> 325.29322 | J23: 116.46968 | K23: 6882.5332 | L23: 1073.0998 | M23: 5168.469 | N23: 5329.1546 | O23: 195548000 | P23: =+(G23/O23)*100 -> 0.00034674789
A24: DAES | B24: Cooperativa de Ahorro y Crédito Bansur | C24: 65002821-K | D24: 2020 | E24: 1039.6192 | F24: =0.3776*E24 -> 392.56021 | G24: =+E24-F24 -> 647.05899 | H24: 345.74504 | I24: =+G24-H24 -> 301.31394 | J24: 6.20403 | K24: 7186.0343 | L24: 1113.4539 | M24: 6029.6582 | N24: 4497.5351 | O24: 201307000 | P24: =+(G24/O24)*100 -> 0.00032142895
A25: DAES | B25: Cooperativa de Ahorro y Crédito Bansur | C25: 65002821-K | D25: 2021 | E25: 1117.9335 | F25: =0.3776*E25 -> 422.13168 | G25: =+E25-F25 -> 695.80179 | H25: 327.75752 | I25: =+G25-H25 -> 368.04427 | J25: 105.1855 | K25: 7292.0895 | L25: 1336.7627 | M25: 5902.8012 | N25: 4979.9877 | O25: 239556000 | P25: =+(G25/O25)*100 -> 0.00029045475
A26: DAES | B26: Cooperativa de Ahorro y Crédito Bansur | C26: 65002821-K | D26: 2022 | E26: 1485.3753 | F26: =0.3776*E26 -> 560.87772 | G26: =+E26-F26 -> 924.49761 | H26: 391.89795 | I26: =+G26-H26 -> 532.59966 | J26: 42.594128 | K26: 8250.3409 | L26: 1765.2139 | M26: 6405.6976 | N26: 6453.6491 | O26: 262954000 | P26: =+(G26/O26)*100 -> 0.0003515815
A27: DAES | B27: Cooperativa de Ahorro y Crédito Bansur | C27: 65002821-K | D27: 2023 | E27: 1740.0087 | F27: =0.3776*E27 -> 657.0273 | G27: =+E27-F27 -> 1082.9814 | H27: 416.08872 | I27: =+G27-H27 -> 666.89272 | J27: 40.183435 | K27: 10172.81 | L27: 1853.6455 | M27: 8143.1628 | N27: 7006.3356 | O27: 282097000 | P27: =+(G27/O27)*100 -> 0.00038390392
A28: DAES | B28: Cooperativa de Ahorro y Crédito Cajanova | C28: 65461730-9 | D28: 2020 | E28: 259.09107 | F28: =0.3776*E28 -> 97.832787 | G28: =+E28-F28 -> 161.25828 | H28: 94.295685 | I28: =+G28-H28 -> 66.962594 | J28: 23.530015 | K28: 2384.8037 | L28: 1188.517 | M28: 1129.6605 | N28: 2069.955 | O28: 201307000 | P28: =+(G28/O28)*100 -> 8.0105649e-05
A29: DAES | B29: Cooperativa de Ahorro y Crédito Cajanova | C29: 65461730-9 | D29: 2021 | E29: 237.66831 | F29: =0.3776*E29 -> 89.743553 | G29: =+E29-F29 -> 147.92476 | H29: 87.097456 | I29: =+G29-H29 -> 60.8273 | J29: 16.322393 | K29: 1941.5712 | L29: 1214.5392 | M29: 710.68891 | N29: 1560.2638 | O29: 239556000 | P29: =+(G29/O29)*100 -> 6.1749551e-05
A30: DAES | B30: Cooperativa de Ahorro y Crédito Cajanova | C30: 65461730-9 | D30: 2022 | E30: 510.6114 | F30: =0.3776*E30 -> 192.80686 | G30: =+E30-F30 -> 317.80453 | H30: 82.871102 | I30: =+G30-H30 -> 234.93343 | J30: 34.302946 | K30: 2055.2634 | L30: 1395.8106 | M30: 217.98501 | N30: 1848.8221 | O30: 262954000 | P30: =+(G30/O30)*100 -> 0.00012085936
A31: DAES | B31: Cooperativa de Ahorro y Crédito Cajanova | C31: 65461730-9 | D31: 2023 | E31: 286.65637 | F31: =0.3776*E31 -> 108.24144 | G31: =+E31-F31 -> 178.41492 | H31: 104.31564 | I31: =+G31-H31 -> 74.099286 | J31: -183.41869 | K31: 6665.4839 | L31: 1327.8182 | M31: 5247.9737 | N31: 1217.8318 | O31: 282097000 | P31: =+(G31/O31)*100 -> 6.3245949e-05
... A33: DAES | B33: Cooperativa de Ahorro y Crédito Coosagro Ltda | C33: 70022600-K | D33: 2023 | E33: 88.925671 | F33: =0.3776*E33 -> 33.578333 | G33: =+E33-F33 -> 55.347338 | H33: 34.868674 | I33: =+G33-H33 -> 20.478664 | J33: 9.077125 | K33: 632.05359 | L33: 579.28116 | M33: 7.546419 | N33: 318.53043 | O33: 282097000 | P33: =+(G33/O33)*100 -> 1.9619967e-05
A34: DAES | B34: Cooperativa de Ahorro y Crédito de Educadores | C34: 70350700-K | D34: 2017 | E34: 370.30518 | F34: =0.3776*E34 -> 139.82724 | G34: =+E34-F34 -> 230.47794 | H34: 343.64814 | I34: =+G34-H34 -> -113.1702 | J34: -267.82745 | K34: 1331.7833 | L34: 1180.9397 | N34: 766.8104 | O34: 179315000 | P34: =+(G34/O34)*100 -> 0.00012853244
A35: DAES | B35: Cooperativa de Ahorro y Crédito de Educadores | C35: 70350700-K | D35: 2018 | E35: 275.19539 | F35: =0.3776*E35 -> 103.91378 | G35: =+E35-F35 -> 171.28161 | H35: 285.65081 | I35: =+G35-H35 -> -114.3692 | J35: -158.69278 | K35: 1119.831 | L35: 1024.0861 | N35: 580.33956 | O35: 189435000 | P35: =+(G35/O35)*100 -> 9.0417087e-05
A36: DAES | B36: Cooperativa de Ahorro y Crédito Dreves Limita | C36: 83990500-9 | D36: 2017 | F36: =0.3776*E36 -> 0 | G36: =+E36-F36 -> 0 | H36: 86.666 | I36: =+G36-H36 -> -86.666 | J36: -96.234 | K36: 183.104 | L36: 94.413 | O36: 179315000 | P36: =+(G36/O36)*100 -> 0
A37: DAES | B37: Cooperativa de Ahorro y Crédito Dreves Limita | C37: 83990500-9 | D37: 2018 | F37: =0.3776*E37 -> 0 | G37: =+E37-F37 -> 0 | H37: 70.504 | I37: =+G37-H37 -> -70.504 | J37: -66.778 | K37: 98.651 | L37: 12.057 | O37: 189435000 | P37: =+(G37/O37)*100 -> 0
A38: DAES | B38: Cooperativa de Ahorro y Crédito Endógena Mapu | C38: 65111485-3 | D38: 2015 | E38: 0 | F38: =0.3776*E38 -> 0 | G38: =+E38-F38 -> 0 | I38: =+G38-H38 -> 0 | J38: -0.000112 | K38: 0.02802 | L38: 0.02802 | M38: 0 | N38: 0 | O38: 158623000 | P38: =+(G38/O38)*100 -> 0
A39: DAES | B39: Cooperativa de Ahorro y Crédito Endógena Mapu | C39: 65111485-3 | D39: 2016 | E39: 0.002191 | F39: =0.3776*E39 -> 0.0008273216 | G39: =+E39-F39 -> 0.0013636784 | I39: =+G39-H39 -> 0.0013636784 | J39: -0.017597 | K39: 0.026606 | L39: 0.023667 | M39: 0 | N39: 0.011761 | O39: 168765000 | P39: =+(G39/O39)*100 -> 8.0803389e-10
A40: DAES | B40: Cooperativa de Ahorro y Crédito Endógena Mapu | C40: 65111485-3 | D40: 2017 | F40: =0.3776*E40 -> 0 | G40: =+E40-F40 -> 0 | H40: 11.793 | I40: =+G40-H40 -> -11.793 | J40: 1.686 | K40: 47.656 | L40: 43.527 | O40: 179315000 | P40: =+(G40/O40)*100 -> 0
A41: DAES | B41: Cooperativa de Ahorro y Crédito Endógena Mapu | C41: 65111485-3 | D41: 2018 | F41: =0.3776*E41 -> 0 | G41: =+E41-F41 -> 0 | H41: 19.603 | I41: =+G41-H41 -> -19.603 | J41: -5.171 | K41: 62.722 | L41: 58.197 | O41: 189435000 | P41: =+(G41/O41)*100 -> 0
...

Sheet 📁 Panel CMF
A1: PANEL DE DATOS — UNA FILA POR COOPERATIVA × AÑO
A2: Segmento | B2: Entidad | C2: RUT | D2: Año | E2: P1 (MM$) | F2: P2 (MM$) | G2: B1g (MM$) | H2: D1 (MM$) | I2: B2g (MM$) | J2: Rem (MM$) | K2: F2 (MM$) | L2: F4 (MM$) | M2: Activos (MM$) | N2: Patrimonio (MM$) | O2: PIB_MM | P2: Aporte (%)
A3: CMF | B3: AHORROCOOP | C3: 70.014.500-0 | D3: 2013 | E3: 6948.1 | F3: =0.3776*E3 -> 2623.6026 | G3: =+E3-F3 -> 4324.4974 | H3: 3146.5 | I3: =+G3-H3 -> 1177.9974 | J3: -1580.6 | K3: 20566.8 | L3: 25922 | M3: 32276.2 | N3: 11120.3 | O3: 136003000 | P3: =+(G3/O3)*100 -> 0.0031797074
A4: CMF | B4: AHORROCOOP | C4: 70.014.500-0 | D4: 2014 | E4: 5701.9 | F4: =0.3776*E4 -> 2153.0374 | G4: =+E4-F4 -> 3548.8626 | H4: 2930.6 | I4: =+G4-H4 -> 618.26256 | J4: -4951.7 | K4: 20696.8 | L4: 19610.9 | M4: 27036.7 | N4: 5788.6 | O4: 144706000 | P4: =+(G4/O4)*100 -> 0.002452464
A5: CMF | B5: AHORROCOOP | C5: 70.014.500-0 | D5: 2015 | E5: 5838.4 | F5: =0.3776*E5 -> 2204.5798 | G5: =+E5-F5 -> 3633.8202 | H5: 2625.4 | I5: =+G5-H5 -> 1008.4202 | J5: -1295.7 | K5: 23133.7 | L5: 22045.1 | M5: 28433 | N5: 4742.8 | O5: 158623000 | P5: =+(G5/O5)*100 -> 0.0022908533
A6: CMF | B6: AHORROCOOP | C6: 70.014.500-0 | D6: 2016 | E6: 7215 | F6: =0.3776*E6 -> 2724.384 | G6: =+E6-F6 -> 4490.616 | H6: 2822.3 | I6: =+G6-H6 -> 1668.316 | J6: 360.1 | K6: 27470.5 | L6: 26592.6 | M6: 33393.5 | N6: 5265.1 | O6: 168765000 | P6: =+(G6/O6)*100 -> 0.0026608693
A7: CMF | B7: AHORROCOOP | C7: 70.014.500-0 | D7: 2017 | E7: 5915 | F7: =0.3776*E7 -> 2233.504 | G7: =+E7-F7 -> 3681.496 | H7: 2687 | I7: =+G7-H7 -> 994.496 | J7: 488 | K7: 29778 | L7: 35242 | M7: 37342 | N7: 4357 | O7: 179315000 | P7: =+(G7/O7)*100 -> 0.0020530887
A8: CMF | B8: AHORROCOOP | C8: 70.014.500-0 | D8: 2018 | E8: 7611 | F8: =0.3776*E8 -> 2873.9136 | G8: =+E8-F8 -> 4737.0864 | H8: 3158 | I8: =+G8-H8 -> 1579.0864 | J8: 1661 | K8: 35345 | L8: 29764 | M8: 42902 | N8: 6131 | O8: 189435000 | P8: =+(G8/O8)*100 -> 0.0025006395
A9: CMF | B9: AHORROCOOP | C9: 70.014.500-0 | D9: 2019 | E9: 8768 | F9: =0.3776*E9 -> 3310.7968 | G9: =+E9-F9 -> 5457.2032 | H9: 3350 | I9: =+G9-H9 -> 2107.2032 | J9: 2112 | K9: 40476 | L9: 40909 | M9: 50812 | N9: 8617 | O9: 195548000 | P9: =+(G9/O9)*100 -> 0.0027907231
A10: CMF | B10: AHORROCOOP | C10: 70.014.500-0 | D10: 2020 | E10: 8612 | F10: =0.3776*E10 -> 3251.8912 | G10: =+E10-F10 -> 5360.1088 | H10: 3550 | I10: =+G10-H10 -> 1810.1088 | J10: 1538 | K10: 44291 | L10: 40506 | M10: 54171 | N10: 10150 | O10: 201307000 | P10: =+(G10/O10)*100 -> 0.002662654
A11: CMF | B11: AHORROCOOP | C11: 70.014.500-0 | D11: 2021 | E11: 9254 | F11: =0.3776*E11 -> 3494.3104 | G11: =+E11-F11 -> 5759.6896 | H11: 3836 | I11: =+G11-H11 -> 1923.6896 | J11: 3542 | K11: 42108 | L11: 48654 | M11: 58971 | N11: 12549 | O11: 239556000 | P11: =+(G11/O11)*100 -> 0.0024043187
A12: CMF | B12: AHORROCOOP | C12: 70.014.500-0 | D12: 2022 | E12: 11783 | F12: =0.3776*E12 -> 4449.2608 | G12: =+E12-F12 -> 7333.7392 | H12: 4794 | I12: =+G12-H12 -> 2539.7392 | J12: 3552 | K12: 48169 | L12: 60155 | M12: 68830 | N12: 15234 | O12: 262954000 | P12: =+(G12/O12)*100 -> 0.0027889818
A13: CMF | B13: AHORROCOOP | C13: 70.014.500-0 | D13: 2023 | E13: 11267 | F13: =0.3776*E13 -> 4254.4192 | G13: =+E13-F13 -> 7012.5808 | H13: 5515 | I13: =+G13-H13 -> 1497.5808 | J13: 1623 | K13: 56129 | L13: 70304 | M13: 77988 | N13: 17876 | O13: 282097000 | P13: =+(G13/O13)*100 -> 0.0024858757
A14: CMF | B14: AHORROCOOP | C14: 70.014.500-0 | D14: 2024 | E14: 13928 | F14: =0.3776*E14 -> 5259.2128 | G14: =+E14-F14 -> 8668.7872 | H14: 6309 | I14: =+G14-H14 -> 2359.7872 | J14: 1702 | K14: 67995 | L14: 79312 | M14: 91740 | N14: 19676 | O14: 310681000 | P14: =+(G14/O14)*100 -> 0.0027902534
